Workbook

Sheet Master Score
A1: Date | B1: Group | C1: Home | D1: Away | E1: Score | G1: Result | H1: Goals | I1: Group | J1: A | K1: B | L1: C | M1: D | N1: E | O1: F | P1: G | Q1: H | R1: I | S1: J | T1: K | U1: L
A2: 46184 | B2: A | C2: Mexico | D2: South Africa | E2: 2 | F2: 0 | G2: =IF(OR(E2="",F2=""),"",IF(E2>F2,1,IF(F2>E2,2,"X"))) -> 1 | H2: =SUM(E2:F2) -> 2 | I2: 1st | J2: {=INDEX(_xlfn.SORTBY(_xlfn._xlws.FILTER($C$78:$E$125,$B$78:$B$125="A"),_xlfn._xlws.FILTER($D$78:$D$125,$B$78:$B$125="A"),-1,_xlfn._xlws.FILTER($E$78:$E$125,$B$78:$B$125="A"),-1),1,1)} -> Mexico | K2: {=INDEX(_xlfn.SORTBY(_xlfn._xlws.FILTER($C$78:$E$125,$B$78:$B$125="B"),_xlfn._xlws.FILTER($D$78:$D$125,$B$78:$B$125="B"),-1,_xlfn._xlws.FILTER($E$78:$E$125,$B$78:$B$125="B"),-1),1,1)} -> Bosnia and Herzegovina | L2: {=INDEX(_xlfn.SORTBY(_xlfn._xlws.FILTER($C$78:$E$125,$B$78:$B$125="C"),_xlfn._xlws.FILTER($D$78:$D$125,$B$78:$B$125="C"),-1,_xlfn._xlws.FILTER($E$78:$E$125,$B$78:$B$125="C"),-1),1,1)} -> Brazil | M2: {=INDEX(_xlfn.SORTBY(_xlfn._xlws.FILTER($C$78:$E$125,$B$78:$B$125="D"),_xlfn._xlws.FILTER($D$78:$D$125,$B$78:$B$125="D"),-1,_xlfn._xlws.FILTER($E$78:$E$125,$B$78:$B$125="D"),-1),1,1)} -> Australia | N2: {=INDEX(_xlfn.SORTBY(_xlfn._xlws.FILTER($C$78:$E$125,$B$78:$B$125="E"),_xlfn._xlws.FILTER($D$78:$D$125,$B$78:$B$125="E"),-1,_xlfn._xlws.FILTER($E$78:$E$125,$B$78:$B$125="E"),-1),1,1)} -> Curaçao | O2: {=INDEX(_xlfn.SORTBY(_xlfn._xlws.FILTER($C$78:$E$125,$B$78:$B$125="F"),_xlfn._xlws.FILTER($D$78:$D$125,$B$78:$B$125="F"),-1,_xlfn._xlws.FILTER($E$78:$E$125,$B$78:$B$125="F"),-1),1,1)} -> Japan | P2: {=INDEX(_xlfn.SORTBY(_xlfn._xlws.FILTER($C$78:$E$125,$B$78:$B$125="G"),_xlfn._xlws.FILTER($D$78:$D$125,$B$78:$B$125="G"),-1,_xlfn._xlws.FILTER($E$78:$E$125,$B$78:$B$125="G"),-1),1,1)} -> Belgium | Q2: {=INDEX(_xlfn.SORTBY(_xlfn._xlws.FILTER($C$78:$E$125,$B$78:$B$125="H"),_xlfn._xlws.FILTER($D$78:$D$125,$B$78:$B$125="H"),-1,_xlfn._xlws.FILTER($E$78:$E$125,$B$78:$B$125="H"),-1),1,1)} -> Cabo Verde | R2: {=INDEX(_xlfn.SORTBY(_xlfn._xlws.FILTER($C$78:$E$125,$B$78:$B$125="I"),_xlfn._xlws.FILTER($D$78:$D$125,$B$78:$B$125="I"),-1,_xlfn._xlws.FILTER($E$78:$E$125,$B$78:$B$125="I"),-1),1,1)} -> France | S2: {=INDEX(_xlfn.SORTBY(_xlfn._xlws.FILTER($C$78:$E$125,$B$78:$B$125="J"),_xlfn._xlws.FILTER($D$78:$D$125,$B$78:$B$125="J"),-1,_xlfn._xlws.FILTER($E$78:$E$125,$B$78:$B$125="J"),-1),1,1)} -> Algeria | T2: {=INDEX(_xlfn.SORTBY(_xlfn._xlws.FILTER($C$78:$E$125,$B$78:$B$125="K"),_xlfn._xlws.FILTER($D$78:$D$125,$B$78:$B$125="K"),-1,_xlfn._xlws.FILTER($E$78:$E$125,$B$78:$B$125="K"),-1),1,1)} -> Colombia | U2: {=INDEX(_xlfn.SORTBY(_xlfn._xlws.FILTER($C$78:$E$125,$B$78:$B$125="L"),_xlfn._xlws.FILTER($D$78:$D$125,$B$78:$B$125="L"),-1,_xlfn._xlws.FILTER($E$78:$E$125,$B$78:$B$125="L"),-1),1,1)} -> Croatia
A3: 46185 | B3: A | C3: South Korea | D3: Czechia | E3: 2 | F3: 1 | G3: =IF(OR(E3="",F3=""),"",IF(E3>F3,1,IF(F3>E3,2,"X"))) -> 1 | H3: =SUM(E3:F3) -> 3 | I3: 2nd | J3: {=INDEX(_xlfn.SORTBY(_xlfn._xlws.FILTER($C$78:$E$125,$B$78:$B$125="A"),_xlfn._xlws.FILTER($D$78:$D$125,$B$78:$B$125="A"),-1,_xlfn._xlws.FILTER($E$78:$E$125,$B$78:$B$125="A"),-1),2,1)} -> South Korea | K3: {=INDEX(_xlfn.SORTBY(_xlfn._xlws.FILTER($C$78:$E$125,$B$78:$B$125="B"),_xlfn._xlws.FILTER($D$78:$D$125,$B$78:$B$125="B"),-1,_xlfn._xlws.FILTER($E$78:$E$125,$B$78:$B$125="B"),-1),2,1)} -> Canada | L3: {=INDEX(_xlfn.SORTBY(_xlfn._xlws.FILTER($C$78:$E$125,$B$78:$B$125="C"),_xlfn._xlws.FILTER($D$78:$D$125,$B$78:$B$125="C"),-1,_xlfn._xlws.FILTER($E$78:$E$125,$B$78:$B$125="C"),-1),2,1)} -> Haiti | M3: {=INDEX(_xlfn.SORTBY(_xlfn._xlws.FILTER($C$78:$E$125,$B$78:$B$125="D"),_xlfn._xlws.FILTER($D$78:$D$125,$B$78:$B$125="D"),-1,_xlfn._xlws.FILTER($E$78:$E$125,$B$78:$B$125="D"),-1),2,1)} -> Paraguay | N3: {=INDEX(_xlfn.SORTBY(_xlfn._xlws.FILTER($C$78:$E$125,$B$78:$B$125="E"),_xlfn._xlws.FILTER($D$78:$D$125,$B$78:$B$125="E"),-1,_xlfn._xlws.FILTER($E$78:$E$125,$B$78:$B$125="E"),-1),2,1)} -> Côte d'Ivoire | O3: {=INDEX(_xlfn.SORTBY(_xlfn._xlws.FILTER($C$78:$E$125,$B$78:$B$125="F"),_xlfn._xlws.FILTER($D$78:$D$125,$B$78:$B$125="F"),-1,_xlfn._xlws.FILTER($E$78:$E$125,$B$78:$B$125="F"),-1),2,1)} -> Netherlands | P3: {=INDEX(_xlfn.SORTBY(_xlfn._xlws.FILTER($C$78:$E$125,$B$78:$B$125="G"),_xlfn._xlws.FILTER($D$78:$D$125,$B$78:$B$125="G"),-1,_xlfn._xlws.FILTER($E$78:$E$125,$B$78:$B$125="G"),-1),2,1)} -> Egypt | Q3: {=INDEX(_xlfn.SORTBY(_xlfn._xlws.FILTER($C$78:$E$125,$B$78:$B$125="H"),_xlfn._xlws.FILTER($D$78:$D$125,$B$78:$B$125="H"),-1,_xlfn._xlws.FILTER($E$78:$E$125,$B$78:$B$125="H"),-1),2,1)} -> Saudi Arabia | R3: {=INDEX(_xlfn.SORTBY(_xlfn._xlws.FILTER($C$78:$E$125,$B$78:$B$125="I"),_xlfn._xlws.FILTER($D$78:$D$125,$B$78:$B$125="I"),-1,_xlfn._xlws.FILTER($E$78:$E$125,$B$78:$B$125="I"),-1),2,1)} -> Iraq | S3: {=INDEX(_xlfn.SORTBY(_xlfn._xlws.FILTER($C$78:$E$125,$B$78:$B$125="J"),_xlfn._xlws.FILTER($D$78:$D$125,$B$78:$B$125="J"),-1,_xlfn._xlws.FILTER($E$78:$E$125,$B$78:$B$125="J"),-1),2,1)} -> Argentina | T3: {=INDEX(_xlfn.SORTBY(_xlfn._xlws.FILTER($C$78:$E$125,$B$78:$B$125="K"),_xlfn._xlws.FILTER($D$78:$D$125,$B$78:$B$125="K"),-1,_xlfn._xlws.FILTER($E$78:$E$125,$B$78:$B$125="K"),-1),2,1)} -> Congo DR | U3: {=INDEX(_xlfn.SORTBY(_xlfn._xlws.FILTER($C$78:$E$125,$B$78:$B$125="L"),_xlfn._xlws.FILTER($D$78:$D$125,$B$78:$B$125="L"),-1,_xlfn._xlws.FILTER($E$78:$E$125,$B$78:$B$125="L"),-1),2,1)} -> England
A4: 46185 | B4: B | C4: Canada | D4: Bosnia and Herzegovina | E4: 1 | F4: 1 | G4: =IF(OR(E4="",F4=""),"",IF(E4>F4,1,IF(F4>E4,2,"X"))) -> X | H4: =SUM(E4:F4) -> 2 | I4: 3rd | J4: {=INDEX(_xlfn.SORTBY(_xlfn._xlws.FILTER($C$78:$E$125,$B$78:$B$125="A"),_xlfn._xlws.FILTER($D$78:$D$125,$B$78:$B$125="A"),-1,_xlfn._xlws.FILTER($E$78:$E$125,$B$78:$B$125="A"),-1),3,1)} -> Czechia | K4: {=INDEX(_xlfn.SORTBY(_xlfn._xlws.FILTER($C$78:$E$125,$B$78:$B$125="B"),_xlfn._xlws.FILTER($D$78:$D$125,$B$78:$B$125="B"),-1,_xlfn._xlws.FILTER($E$78:$E$125,$B$78:$B$125="B"),-1),3,1)} -> Qatar | L4: {=INDEX(_xlfn.SORTBY(_xlfn._xlws.FILTER($C$78:$E$125,$B$78:$B$125="C"),_xlfn._xlws.FILTER($D$78:$D$125,$B$78:$B$125="C"),-1,_xlfn._xlws.FILTER($E$78:$E$125,$B$78:$B$125="C"),-1),3,1)} -> Morocco | M4: {=INDEX(_xlfn.SORTBY(_xlfn._xlws.FILTER($C$78:$E$125,$B$78:$B$125="D"),_xlfn._xlws.FILTER($D$78:$D$125,$B$78:$B$125="D"),-1,_xlfn._xlws.FILTER($E$78:$E$125,$B$78:$B$125="D"),-1),3,1)} -> Türkiye | N4: {=INDEX(_xlfn.SORTBY(_xlfn._xlws.FILTER($C$78:$E$125,$B$78:$B$125="E"),_xlfn._xlws.FILTER($D$78:$D$125,$B$78:$B$125="E"),-1,_xlfn._xlws.FILTER($E$78:$E$125,$B$78:$B$125="E"),-1),3,1)} -> Ecuador | O4: {=INDEX(_xlfn.SORTBY(_xlfn._xlws.FILTER($C$78:$E$125,$B$78:$B$125="F"),_xlfn._xlws.FILTER($D$78:$D$125,$B$78:$B$125="F"),-1,_xlfn._xlws.FILTER($E$78:$E$125,$B$78:$B$125="F"),-1),3,1)} -> Sweden | P4: {=INDEX(_xlfn.SORTBY(_xlfn._xlws.FILTER($C$78:$E$125,$B$78:$B$125="G"),_xlfn._xlws.FILTER($D$78:$D$125,$B$78:$B$125="G"),-1,_xlfn._xlws.FILTER($E$78:$E$125,$B$78:$B$125="G"),-1),3,1)} -> IR Iran | Q4: {=INDEX(_xlfn.SORTBY(_xlfn._xlws.FILTER($C$78:$E$125,$B$78:$B$125="H"),_xlfn._xlws.FILTER($D$78:$D$125,$B$78:$B$125="H"),-1,_xlfn._xlws.FILTER($E$78:$E$125,$B$78:$B$125="H"),-1),3,1)} -> Spain | R4: {=INDEX(_xlfn.SORTBY(_xlfn._xlws.FILTER($C$78:$E$125,$B$78:$B$125="I"),_xlfn._xlws.FILTER($D$78:$D$125,$B$78:$B$125="I"),-1,_xlfn._xlws.FILTER($E$78:$E$125,$B$78:$B$125="I"),-1),3,1)} -> Norway | S4: {=INDEX(_xlfn.SORTBY(_xlfn._xlws.FILTER($C$78:$E$125,$B$78:$B$125="J"),_xlfn._xlws.FILTER($D$78:$D$125,$B$78:$B$125="J"),-1,_xlfn._xlws.FILTER($E$78:$E$125,$B$78:$B$125="J"),-1),3,1)} -> Austria | T4: {=INDEX(_xlfn.SORTBY(_xlfn._xlws.FILTER($C$78:$E$125,$B$78:$B$125="K"),_xlfn._xlws.FILTER($D$78:$D$125,$B$78:$B$125="K"),-1,_xlfn._xlws.FILTER($E$78:$E$125,$B$78:$B$125="K"),-1),3,1)} -> Portugal | U4: {=INDEX(_xlfn.SORTBY(_xlfn._xlws.FILTER($C$78:$E$125,$B$78:$B$125="L"),_xlfn._xlws.FILTER($D$78:$D$125,$B$78:$B$125="L"),-1,_xlfn._xlws.FILTER($E$78:$E$125,$B$78:$B$125="L"),-1),3,1)} -> Ghana
A5: 46186 | B5: D | C5: USA | D5: Paraguay | G5: =IF(OR(E5="",F5=""),"",IF(E5>F5,1,IF(F5>E5,2,"X"))) | H5: =SUM(E5:F5) -> 0 | I5: 4th | J5: {=INDEX(_xlfn.SORTBY(_xlfn._xlws.FILTER($C$78:$E$125,$B$78:$B$125="A"),_xlfn._xlws.FILTER($D$78:$D$125,$B$78:$B$125="A"),-1,_xlfn._xlws.FILTER($E$78:$E$125,$B$78:$B$125="A"),-1),4,1)} -> South Africa | K5: {=INDEX(_xlfn.SORTBY(_xlfn._xlws.FILTER($C$78:$E$125,$B$78:$B$125="B"),_xlfn._xlws.FILTER($D$78:$D$125,$B$78:$B$125="B"),-1,_xlfn._xlws.FILTER($E$78:$E$125,$B$78:$B$125="B"),-1),4,1)} -> Switzerland | L5: {=INDEX(_xlfn.SORTBY(_xlfn._xlws.FILTER($C$78:$E$125,$B$78:$B$125="C"),_xlfn._xlws.FILTER($D$78:$D$125,$B$78:$B$125="C"),-1,_xlfn._xlws.FILTER($E$78:$E$125,$B$78:$B$125="C"),-1),4,1)} -> Scotland | M5: {=INDEX(_xlfn.SORTBY(_xlfn._xlws.FILTER($C$78:$E$125,$B$78:$B$125="D"),_xlfn._xlws.FILTER($D$78:$D$125,$B$78:$B$125="D"),-1,_xlfn._xlws.FILTER($E$78:$E$125,$B$78:$B$125="D"),-1),4,1)} -> USA | N5: {=INDEX(_xlfn.SORTBY(_xlfn._xlws.FILTER($C$78:$E$125,$B$78:$B$125="E"),_xlfn._xlws.FILTER($D$78:$D$125,$B$78:$B$125="E"),-1,_xlfn._xlws.FILTER($E$78:$E$125,$B$78:$B$125="E"),-1),4,1)} -> Germany | O5: {=INDEX(_xlfn.SORTBY(_xlfn._xlws.FILTER($C$78:$E$125,$B$78:$B$125="F"),_xlfn._xlws.FILTER($D$78:$D$125,$B$78:$B$125="F"),-1,_xlfn._xlws.FILTER($E$78:$E$125,$B$78:$B$125="F"),-1),4,1)} -> Tunisia | P5: {=INDEX(_xlfn.SORTBY(_xlfn._xlws.FILTER($C$78:$E$125,$B$78:$B$125="G"),_xlfn._xlws.FILTER($D$78:$D$125,$B$78:$B$125="G"),-1,_xlfn._xlws.FILTER($E$78:$E$125,$B$78:$B$125="G"),-1),4,1)} -> New Zealand | Q5: {=INDEX(_xlfn.SORTBY(_xlfn._xlws.FILTER($C$78:$E$125,$B$78:$B$125="H"),_xlfn._xlws.FILTER($D$78:$D$125,$B$78:$B$125="H"),-1,_xlfn._xlws.FILTER($E$78:$E$125,$B$78:$B$125="H"),-1),4,1)} -> Uruguay | R5: {=INDEX(_xlfn.SORTBY(_xlfn._xlws.FILTER($C$78:$E$125,$B$78:$B$125="I"),_xlfn._xlws.FILTER($D$78:$D$125,$B$78:$B$125="I"),-1,_xlfn._xlws.FILTER($E$78:$E$125,$B$78:$B$125="I"),-1),4,1)} -> Senegal | S5: {=INDEX(_xlfn.SORTBY(_xlfn._xlws.FILTER($C$78:$E$125,$B$78:$B$125="J"),_xlfn._xlws.FILTER($D$78:$D$125,$B$78:$B$125="J"),-1,_xlfn._xlws.FILTER($E$78:$E$125,$B$78:$B$125="J"),-1),4,1)} -> Jordan | T5: {=INDEX(_xlfn.SORTBY(_xlfn._xlws.FILTER($C$78:$E$125,$B$78:$B$125="K"),_xlfn._xlws.FILTER($D$78:$D$125,$B$78:$B$125="K"),-1,_xlfn._xlws.FILTER($E$78:$E$125,$B$78:$B$125="K"),-1),4,1)} -> Uzbekistan | U5: {=INDEX(_xlfn.SORTBY(_xlfn._xlws.FILTER($C$78:$E$125,$B$78:$B$125="L"),_xlfn._xlws.FILTER($D$78:$D$125,$B$78:$B$125="L"),-1,_xlfn._xlws.FILTER($E$78:$E$125,$B$78:$B$125="L"),-1),4,1)} -> Panama
A6: 46186 | B6: B | C6: Qatar | D6: Switzerland | G6: =IF(OR(E6="",F6=""),"",IF(E6>F6,1,IF(F6>E6,2,"X"))) | H6: =SUM(E6:F6) -> 0
A7: 46186 | B7: C | C7: Brazil | D7: Morocco | G7: =IF(OR(E7="",F7=""),"",IF(E7>F7,1,IF(F7>E7,2,"X"))) | H7: =SUM(E7:F7) -> 0
A8: 46187 | B8: C | C8: Haiti | D8: Scotland | G8: =IF(OR(E8="",F8=""),"",IF(E8>F8,1,IF(F8>E8,2,"X"))) | H8: =SUM(E8:F8) -> 0
A9: 46187 | B9: D | C9: Australia | D9: Türkiye | G9: =IF(OR(E9="",F9=""),"",IF(E9>F9,1,IF(F9>E9,2,"X"))) | H9: =SUM(E9:F9) -> 0
A10: 46187 | B10: E | C10: Germany | D10: Curaçao | G10: =IF(OR(E10="",F10=""),"",IF(E10>F10,1,IF(F10>E10,2,"X"))) | H10: =SUM(E10:F10) -> 0
A11: 46187 | B11: F | C11: Netherlands | D11: Japan | G11: =IF(OR(E11="",F11=""),"",IF(E11>F11,1,IF(F11>E11,2,"X"))) | H11: =SUM(E11:F11) -> 0
A12: 46188 | B12: E | C12: Côte d'Ivoire | D12: Ecuador | G12: =IF(OR(E12="",F12=""),"",IF(E12>F12,1,IF(F12>E12,2,"X"))) | H12: =SUM(E12:F12) -> 0
A13: 46188 | B13: F | C13: Sweden | D13: Tunisia | G13: =IF(OR(E13="",F13=""),"",IF(E13>F13,1,IF(F13>E13,2,"X"))) | H13: =SUM(E13:F13) -> 0
A14: 46188 | B14: G | C14: Belgium | D14: Egypt | G14: =IF(OR(E14="",F14=""),"",IF(E14>F14,1,IF(F14>E14,2,"X"))) | H14: =SUM(E14:F14) -> 0
A15: 46188 | B15: H | C15: Spain | D15: Cabo Verde | G15: =IF(OR(E15="",F15=""),"",IF(E15>F15,1,IF(F15>E15,2,"X"))) | H15: =SUM(E15:F15) -> 0
A16: 46188 | B16: H | C16: Saudi Arabia | D16: Uruguay | G16: =IF(OR(E16="",F16=""),"",IF(E16>F16,1,IF(F16>E16,2,"X"))) | H16: =SUM(E16:F16) -> 0
A17: 46189 | B17: G | C17: IR Iran | D17: New Zealand | G17: =IF(OR(E17="",F17=""),"",IF(E17>F17,1,IF(F17>E17,2,"X"))) | H17: =SUM(E17:F17) -> 0
... A73: 46201 | B73: K | C73: Congo DR | D73: Uzbekistan | G73: =IF(OR(E73="",F73=""),"",IF(E73>F73,1,IF(F73>E73,2,"X"))) | H73: =SUM(E73:F73) -> 0
H74: =SUM(H2:H73) -> 7
B77: Group | C77: Team | D77: Points | E77: Goal Difference
B78: =IFERROR(INDEX($B$2:$B$73,MATCH(C78,$C$2:$C$73,0)),INDEX($B$2:$B$73,MATCH(C78,$D$2:$D$73,0))) -> A | C78: Mexico | D78: {=SUMPRODUCT((($C$2:$C$73=C78)*($G$2:$G$73=1))*3) + SUMPRODUCT((($D$2:$D$73=C78)*($G$2:$G$73=2))*3) + SUMPRODUCT((($C$2:$C$73=C78)+($D$2:$D$73=C78))*($G$2:$G$73="X"))} -> 3 | E78: {=SUMPRODUCT(($C$2:$C$73=C78)*$E$2:$E$73)+SUMPRODUCT(($D$2:$D$73=C78)*$F$2:$F$73)-SUMPRODUCT(($C$2:$C$73=C78)*$F$2:$F$73)-SUMPRODUCT(($D$2:$D$73=C78)*$E$2:$E$73)} -> 2
B79: =IFERROR(INDEX($B$2:$B$73,MATCH(C79,$C$2:$C$73,0)),INDEX($B$2:$B$73,MATCH(C79,$D$2:$D$73,0))) -> A | C79: Czechia | D79: {=SUMPRODUCT((($C$2:$C$73=C79)*($G$2:$G$73=1))*3) + SUMPRODUCT((($D$2:$D$73=C79)*($G$2:$G$73=2))*3) + SUMPRODUCT((($C$2:$C$73=C79)+($D$2:$D$73=C79))*($G$2:$G$73="X"))} -> 0 | E79: {=SUMPRODUCT(($C$2:$C$73=C79)*$E$2:$E$73)+SUMPRODUCT(($D$2:$D$73=C79)*$F$2:$F$73)-SUMPRODUCT(($C$2:$C$73=C79)*$F$2:$F$73)-SUMPRODUCT(($D$2:$D$73=C79)*$E$2:$E$73)} -> -1
B80: =IFERROR(INDEX($B$2:$B$73,MATCH(C80,$C$2:$C$73,0)),INDEX($B$2:$B$73,MATCH(C80,$D$2:$D$73,0))) -> A | C80: South Africa | D80: {=SUMPRODUCT((($C$2:$C$73=C80)*($G$2:$G$73=1))*3) + SUMPRODUCT((($D$2:$D$73=C80)*($G$2:$G$73=2))*3) + SUMPRODUCT((($C$2:$C$73=C80)+($D$2:$D$73=C80))*($G$2:$G$73="X"))} -> 0 | E80: {=SUMPRODUCT(($C$2:$C$73=C80)*$E$2:$E$73)+SUMPRODUCT(($D$2:$D$73=C80)*$F$2:$F$73)-SUMPRODUCT(($C$2:$C$73=C80)*$F$2:$F$73)-SUMPRODUCT(($D$2:$D$73=C80)*$E$2:$E$73)} -> -2
B81: =IFERROR(INDEX($B$2:$B$73,MATCH(C81,$C$2:$C$73,0)),INDEX($B$2:$B$73,MATCH(C81,$D$2:$D$73,0))) -> A | C81: South Korea | D81: {=SUMPRODUCT((($C$2:$C$73=C81)*($G$2:$G$73=1))*3) + SUMPRODUCT((($D$2:$D$73=C81)*($G$2:$G$73=2))*3) + SUMPRODUCT((($C$2:$C$73=C81)+($D$2:$D$73=C81))*($G$2:$G$73="X"))} -> 3 | E81: {=SUMPRODUCT(($C$2:$C$73=C81)*$E$2:$E$73)+SUMPRODUCT(($D$2:$D$73=C81)*$F$2:$F$73)-SUMPRODUCT(($C$2:$C$73=C81)*$F$2:$F$73)-SUMPRODUCT(($D$2:$D$73=C81)*$E$2:$E$73)} -> 1
B82: =IFERROR(INDEX($B$2:$B$73,MATCH(C82,$C$2:$C$73,0)),INDEX($B$2:$B$73,MATCH(C82,$D$2:$D$73,0))) -> B | C82: Bosnia and Herzegovina | D82: {=SUMPRODUCT((($C$2:$C$73=C82)*($G$2:$G$73=1))*3) + SUMPRODUCT((($D$2:$D$73=C82)*($G$2:$G$73=2))*3) + SUMPRODUCT((($C$2:$C$73=C82)+($D$2:$D$73=C82))*($G$2:$G$73="X"))} -> 1 | E82: {=SUMPRODUCT(($C$2:$C$73=C82)*$E$2:$E$73)+SUMPRODUCT(($D$2:$D$73=C82)*$F$2:$F$73)-SUMPRODUCT(($C$2:$C$73=C82)*$F$2:$F$73)-SUMPRODUCT(($D$2:$D$73=C82)*$E$2:$E$73)} -> 0
B83: =IFERROR(INDEX($B$2:$B$73,MATCH(C83,$C$2:$C$73,0)),INDEX($B$2:$B$73,MATCH(C83,$D$2:$D$73,0))) -> B | C83: Canada | D83: {=SUMPRODUCT((($C$2:$C$73=C83)*($G$2:$G$73=1))*3) + SUMPRODUCT((($D$2:$D$73=C83)*($G$2:$G$73=2))*3) + SUMPRODUCT((($C$2:$C$73=C83)+($D$2:$D$73=C83))*($G$2:$G$73="X"))} -> 1 | E83: {=SUMPRODUCT(($C$2:$C$73=C83)*$E$2:$E$73)+SUMPRODUCT(($D$2:$D$73=C83)*$F$2:$F$73)-SUMPRODUCT(($C$2:$C$73=C83)*$F$2:$F$73)-SUMPRODUCT(($D$2:$D$73=C83)*$E$2:$E$73)} -> 0
B84: =IFERROR(INDEX($B$2:$B$73,MATCH(C84,$C$2:$C$73,0)),INDEX($B$2:$B$73,MATCH(C84,$D$2:$D$73,0))) -> B | C84: Qatar | D84: {=SUMPRODUCT((($C$2:$C$73=C84)*($G$2:$G$73=1))*3) + SUMPRODUCT((($D$2:$D$73=C84)*($G$2:$G$73=2))*3) + SUMPRODUCT((($C$2:$C$73=C84)+($D$2:$D$73=C84))*($G$2:$G$73="X"))} -> 0 | E84: {=SUMPRODUCT(($C$2:$C$73=C84)*$E$2:$E$73)+SUMPRODUCT(($D$2:$D$73=C84)*$F$2:$F$73)-SUMPRODUCT(($C$2:$C$73=C84)*$F$2:$F$73)-SUMPRODUCT(($D$2:$D$73=C84)*$E$2:$E$73)} -> 0
B85: =IFERROR(INDEX($B$2:$B$73,MATCH(C85,$C$2:$C$73,0)),INDEX($B$2:$B$73,MATCH(C85,$D$2:$D$73,0))) -> B | C85: Switzerland | D85: {=SUMPRODUCT((($C$2:$C$73=C85)*($G$2:$G$73=1))*3) + SUMPRODUCT((($D$2:$D$73=C85)*($G$2:$G$73=2))*3) + SUMPRODUCT((($C$2:$C$73=C85)+($D$2:$D$73=C85))*($G$2:$G$73="X"))} -> 0 | E85: {=SUMPRODUCT(($C$2:$C$73=C85)*$E$2:$E$73)+SUMPRODUCT(($D$2:$D$73=C85)*$F$2:$F$73)-SUMPRODUCT(($C$2:$C$73=C85)*$F$2:$F$73)-SUMPRODUCT(($D$2:$D$73=C85)*$E$2:$E$73)} -> 0
B86: =IFERROR(INDEX($B$2:$B$73,MATCH(C86,$C$2:$C$73,0)),INDEX($B$2:$B$73,MATCH(C86,$D$2:$D$73,0))) -> C | C86: Brazil | D86: {=SUMPRODUCT((($C$2:$C$73=C86)*($G$2:$G$73=1))*3) + SUMPRODUCT((($D$2:$D$73=C86)*($G$2:$G$73=2))*3) + SUMPRODUCT((($C$2:$C$73=C86)+($D$2:$D$73=C86))*($G$2:$G$73="X"))} -> 0 | E86: {=SUMPRODUCT(($C$2:$C$73=C86)*$E$2:$E$73)+SUMPRODUCT(($D$2:$D$73=C86)*$F$2:$F$73)-SUMPRODUCT(($C$2:$C$73=C86)*$F$2:$F$73)-SUMPRODUCT(($D$2:$D$73=C86)*$E$2:$E$73)} -> 0
B87: =IFERROR(INDEX($B$2:$B$73,MATCH(C87,$C$2:$C$73,0)),INDEX($B$2:$B$73,MATCH(C87,$D$2:$D$73,0))) -> C | C87: Haiti | D87: {=SUMPRODUCT((($C$2:$C$73=C87)*($G$2:$G$73=1))*3) + SUMPRODUCT((($D$2:$D$73=C87)*($G$2:$G$73=2))*3) + SUMPRODUCT((($C$2:$C$73=C87)+($D$2:$D$73=C87))*($G$2:$G$73="X"))} -> 0 | E87: {=SUMPRODUCT(($C$2:$C$73=C87)*$E$2:$E$73)+SUMPRODUCT(($D$2:$D$73=C87)*$F$2:$F$73)-SUMPRODUCT(($C$2:$C$73=C87)*$F$2:$F$73)-SUMPRODUCT(($D$2:$D$73=C87)*$E$2:$E$73)} -> 0
B88: =IFERROR(INDEX($B$2:$B$73,MATCH(C88,$C$2:$C$73,0)),INDEX($B$2:$B$73,MATCH(C88,$D$2:$D$73,0))) -> C | C88: Morocco | D88: {=SUMPRODUCT((($C$2:$C$73=C88)*($G$2:$G$73=1))*3) + SUMPRODUCT((($D$2:$D$73=C88)*($G$2:$G$73=2))*3) + SUMPRODUCT((($C$2:$C$73=C88)+($D$2:$D$73=C88))*($G$2:$G$73="X"))} -> 0 | E88: {=SUMPRODUCT(($C$2:$C$73=C88)*$E$2:$E$73)+SUMPRODUCT(($D$2:$D$73=C88)*$F$2:$F$73)-SUMPRODUCT(($C$2:$C$73=C88)*$F$2:$F$73)-SUMPRODUCT(($D$2:$D$73=C88)*$E$2:$E$73)} -> 0
B89: =IFERROR(INDEX($B$2:$B$73,MATCH(C89,$C$2:$C$73,0)),INDEX($B$2:$B$73,MATCH(C89,$D$2:$D$73,0))) -> C | C89: Scotland | D89: {=SUMPRODUCT((($C$2:$C$73=C89)*($G$2:$G$73=1))*3) + SUMPRODUCT((($D$2:$D$73=C89)*($G$2:$G$73=2))*3) + SUMPRODUCT((($C$2:$C$73=C89)+($D$2:$D$73=C89))*($G$2:$G$73="X"))} -> 0 | E89: {=SUMPRODUCT(($C$2:$C$73=C89)*$E$2:$E$73)+SUMPRODUCT(($D$2:$D$73=C89)*$F$2:$F$73)-SUMPRODUCT(($C$2:$C$73=C89)*$F$2:$F$73)-SUMPRODUCT(($D$2:$D$73=C89)*$E$2:$E$73)} -> 0
... B125: =IFERROR(INDEX($B$2:$B$73,MATCH(C125,$C$2:$C$73,0)),INDEX($B$2:$B$73,MATCH(C125,$D$2:$D$73,0))) -> L | C125: Panama | D125: {=SUMPRODUCT((($C$2:$C$73=C125)*($G$2:$G$73=1))*3) + SUMPRODUCT((($D$2:$D$73=C125)*($G$2:$G$73=2))*3) + SUMPRODUCT((($C$2:$C$73=C125)+($D$2:$D$73=C125))*($G$2:$G$73="X"))} -> 0 | E125: {=SUMPRODUCT(($C$2:$C$73=C125)*$E$2:$E$73)+SUMPRODUCT(($D$2:$D$73=C125)*$F$2:$F$73)-SUMPRODUCT(($C$2:$C$73=C125)*$F$2:$F$73)-SUMPRODUCT(($D$2:$D$73=C125)*$E$2:$E$73)} -> 0

Sheet Predictions
F1: Matthew O'Brien | H1: =Leaderboard!C3 -> Aaron Twiss | J1: =Leaderboard!C4 -> Arion Aliu | L1: =Leaderboard!C5 -> Rayan Zaibag | N1: =Leaderboard!C6 -> Jorge Lopez
F2: Match | G2: Group | H2: Match | I2: Group | J2: Match | K2: Group | L2: Match | M2: Group | N2: Match | O2: Group
A3: Date | B3: Group | C3: Home | D3: Away | E3: Result | F3: =SUM(G4:G75) -> 2 | G3: =SUM(G78:G125) -> 19 | H3: =SUM(I4:I75) -> 2 | I3: =SUM(I78:I125) -> 12 | J3: =SUM(K4:K75) -> 2 | K3: =SUM(K78:K125) -> 19 | L3: =SUM(M4:M75) -> 2 | M3: =SUM(M78:M125) -> 19 | N3: =SUM(O4:O75) -> 2 | O3: =SUM(O78:O125) -> 13
A4: 46184 | B4: A | C4: Mexico | D4: South Africa | E4: ='Master Score'!G2 -> 1 | F4: 1 | G4: =IF($E4="","",IF(F4=$E4,1,0)) -> 1 | H4: 1 | I4: =IF($E4="","",IF(H4=$E4,1,0)) -> 1 | J4: 1 | K4: =IF($E4="","",IF(J4=$E4,1,0)) -> 1 | L4: 1 | M4: =IF($E4="","",IF(L4=$E4,1,0)) -> 1 | N4: 1 | O4: =IF($E4="","",IF(N4=$E4,1,0)) -> 1
A5: 46185 | B5: A | C5: South Korea | D5: Czechia | E5: ='Master Score'!G3 -> 1 | F5: 1 | G5: =IF($E5="","",IF(F5=$E5,1,0)) -> 1 | H5: X | I5: =IF($E5="","",IF(H5=$E5,1,0)) -> 0 | J5: 1 | K5: =IF($E5="","",IF(J5=$E5,1,0)) -> 1 | L5: X | M5: =IF($E5="","",IF(L5=$E5,1,0)) -> 0 | N5: 1 | O5: =IF($E5="","",IF(N5=$E5,1,0)) -> 1
A6: 46185 | B6: B | C6: Canada | D6: Bosnia and Herzegovina | E6: ='Master Score'!G4 -> X | F6: 1 | G6: =IF($E6="","",IF(F6=$E6,1,0)) -> 0 | H6: X | I6: =IF($E6="","",IF(H6=$E6,1,0)) -> 1 | J6: 2 | K6: =IF($E6="","",IF(J6=$E6,1,0)) -> 0 | L6: X | M6: =IF($E6="","",IF(L6=$E6,1,0)) -> 1 | N6: 1 | O6: =IF($E6="","",IF(N6=$E6,1,0)) -> 0
A7: 46186 | B7: D | C7: USA | D7: Paraguay | E7: ='Master Score'!G5 | F7: 1 | G7: =IF($E7="","",IF(F7=$E7,1,0)) | H7: 2 | I7: =IF($E7="","",IF(H7=$E7,1,0)) | J7: 1 | K7: =IF($E7="","",IF(J7=$E7,1,0)) | L7: 1 | M7: =IF($E7="","",IF(L7=$E7,1,0)) | N7: 1 | O7: =IF($E7="","",IF(N7=$E7,1,0))
A8: 46186 | B8: B | C8: Qatar | D8: Switzerland | E8: ='Master Score'!G6 | F8: 2 | G8: =IF($E8="","",IF(F8=$E8,1,0)) | H8: 2 | I8: =IF($E8="","",IF(H8=$E8,1,0)) | J8: 2 | K8: =IF($E8="","",IF(J8=$E8,1,0)) | L8: 2 | M8: =IF($E8="","",IF(L8=$E8,1,0)) | N8: 2 | O8: =IF($E8="","",IF(N8=$E8,1,0))
A9: 46186 | B9: C | C9: Brazil | D9: Morocco | E9: ='Master Score'!G7 | F9: 1 | G9: =IF($E9="","",IF(F9=$E9,1,0)) | H9: 2 | I9: =IF($E9="","",IF(H9=$E9,1,0)) | J9: 1 | K9: =IF($E9="","",IF(J9=$E9,1,0)) | L9: 1 | M9: =IF($E9="","",IF(L9=$E9,1,0)) | N9: 1 | O9: =IF($E9="","",IF(N9=$E9,1,0))
A10: 46187 | B10: C | C10: Haiti | D10: Scotland | E10: ='Master Score'!G8 | F10: 2 | G10: =IF($E10="","",IF(F10=$E10,1,0)) | H10: 2 | I10: =IF($E10="","",IF(H10=$E10,1,0)) | J10: 2 | K10: =IF($E10="","",IF(J10=$E10,1,0)) | L10: 2 | M10: =IF($E10="","",IF(L10=$E10,1,0)) | N10: 2 | O10: =IF($E10="","",IF(N10=$E10,1,0))
A11: 46187 | B11: D | C11: Australia | D11: Türkiye | E11: ='Master Score'!G9 | F11: 2 | G11: =IF($E11="","",IF(F11=$E11,1,0)) | H11: 2 | I11: =IF($E11="","",IF(H11=$E11,1,0)) | J11: 2 | K11: =IF($E11="","",IF(J11=$E11,1,0)) | L11: 2 | M11: =IF($E11="","",IF(L11=$E11,1,0)) | N11: 2 | O11: =IF($E11="","",IF(N11=$E11,1,0))
A12: 46187 | B12: E | C12: Germany | D12: Curaçao | E12: ='Master Score'!G10 | F12: 1 | G12: =IF($E12="","",IF(F12=$E12,1,0)) | H12: 1 | I12: =IF($E12="","",IF(H12=$E12,1,0)) | J12: 1 | K12: =IF($E12="","",IF(J12=$E12,1,0)) | L12: 1 | M12: =IF($E12="","",IF(L12=$E12,1,0)) | N12: 1 | O12: =IF($E12="","",IF(N12=$E12,1,0))
A13: 46187 | B13: F | C13: Netherlands | D13: Japan | E13: ='Master Score'!G11 | F13: X | G13: =IF($E13="","",IF(F13=$E13,1,0)) | H13: 1 | I13: =IF($E13="","",IF(H13=$E13,1,0)) | J13: 1 | K13: =IF($E13="","",IF(J13=$E13,1,0)) | L13: X | M13: =IF($E13="","",IF(L13=$E13,1,0)) | N13: X | O13: =IF($E13="","",IF(N13=$E13,1,0))
A14: 46188 | B14: E | C14: Côte d'Ivoire | D14: Ecuador | E14: ='Master Score'!G12 | F14: 1 | G14: =IF($E14="","",IF(F14=$E14,1,0)) | H14: X | I14: =IF($E14="","",IF(H14=$E14,1,0)) | J14: 1 | K14: =IF($E14="","",IF(J14=$E14,1,0)) | L14: X | M14: =IF($E14="","",IF(L14=$E14,1,0)) | N14: 2 | O14: =IF($E14="","",IF(N14=$E14,1,0))
A15: 46188 | B15: F | C15: Sweden | D15: Tunisia | E15: ='Master Score'!G13 | F15: 1 | G15: =IF($E15="","",IF(F15=$E15,1,0)) | H15: X | I15: =IF($E15="","",IF(H15=$E15,1,0)) | J15: 1 | K15: =IF($E15="","",IF(J15=$E15,1,0)) | L15: 1 | M15: =IF($E15="","",IF(L15=$E15,1,0)) | N15: 2 | O15: =IF($E15="","",IF(N15=$E15,1,0))
A16: 46188 | B16: G | C16: Belgium | D16: Egypt | E16: ='Master Score'!G14 | F16: 1 | G16: =IF($E16="","",IF(F16=$E16,1,0)) | H16: 1 | I16: =IF($E16="","",IF(H16=$E16,1,0)) | J16: 1 | K16: =IF($E16="","",IF(J16=$E16,1,0)) | L16: 1 | M16: =IF($E16="","",IF(L16=$E16,1,0)) | N16: 1 | O16: =IF($E16="","",IF(N16=$E16,1,0))
A17: 46188 | B17: H | C17: Spain | D17: Cabo Verde | E17: ='Master Score'!G15 | F17: 1 | G17: =IF($E17="","",IF(F17=$E17,1,0)) | H17: 1 | I17: =IF($E17="","",IF(H17=$E17,1,0)) | J17: 1 | K17: =IF($E17="","",IF(J17=$E17,1,0)) | L17: 1 | M17: =IF($E17="","",IF(L17=$E17,1,0)) | N17: 1 | O17: =IF($E17="","",IF(N17=$E17,1,0))
A18: 46188 | B18: H | C18: Saudi Arabia | D18: Uruguay | E18: ='Master Score'!G16 | F18: 2 | G18: =IF($E18="","",IF(F18=$E18,1,0)) | H18: 2 | I18: =IF($E18="","",IF(H18=$E18,1,0)) | J18: 2 | K18: =IF($E18="","",IF(J18=$E18,1,0)) | L18: 2 | M18: =IF($E18="","",IF(L18=$E18,1,0)) | N18: 2 | O18: =IF($E18="","",IF(N18=$E18,1,0))
A19: 46189 | B19: G | C19: IR Iran | D19: New Zealand | E19: ='Master Score'!G17 | F19: X | G19: =IF($E19="","",IF(F19=$E19,1,0)) | H19: 1 | I19: =IF($E19="","",IF(H19=$E19,1,0)) | J19: 2 | K19: =IF($E19="","",IF(J19=$E19,1,0)) | L19: 1 | M19: =IF($E19="","",IF(L19=$E19,1,0)) | N19: 1 | O19: =IF($E19="","",IF(N19=$E19,1,0))
A20: 46189 | B20: I | C20: France | D20: Senegal | E20: ='Master Score'!G18 | F20: 1 | G20: =IF($E20="","",IF(F20=$E20,1,0)) | H20: 1 | I20: =IF($E20="","",IF(H20=$E20,1,0)) | J20: 1 | K20: =IF($E20="","",IF(J20=$E20,1,0)) | L20: 1 | M20: =IF($E20="","",IF(L20=$E20,1,0)) | N20: 1 | O20: =IF($E20="","",IF(N20=$E20,1,0))
A21: 46189 | B21: I | C21: Iraq | D21: Norway | E21: ='Master Score'!G19 | F21: 2 | G21: =IF($E21="","",IF(F21=$E21,1,0)) | H21: 2 | I21: =IF($E21="","",IF(H21=$E21,1,0)) | J21: 2 | K21: =IF($E21="","",IF(J21=$E21,1,0)) | L21: 2 | M21: =IF($E21="","",IF(L21=$E21,1,0)) | N21: 2 | O21: =IF($E21="","",IF(N21=$E21,1,0))
A22: 46190 | B22: J | C22: Argentina | D22: Algeria | E22: ='Master Score'!G20 | F22: 1 | G22: =IF($E22="","",IF(F22=$E22,1,0)) | H22: 1 | I22: =IF($E22="","",IF(H22=$E22,1,0)) | J22: 1 | K22: =IF($E22="","",IF(J22=$E22,1,0)) | L22: 1 | M22: =IF($E22="","",IF(L22=$E22,1,0)) | N22: 1 | O22: =IF($E22="","",IF(N22=$E22,1,0))
A23: 46190 | B23: J | C23: Austria | D23: Jordan | E23: ='Master Score'!G21 | F23: 1 | G23: =IF($E23="","",IF(F23=$E23,1,0)) | H23: 1 | I23: =IF($E23="","",IF(H23=$E23,1,0)) | J23: 1 | K23: =IF($E23="","",IF(J23=$E23,1,0)) | L23: 1 | M23: =IF($E23="","",IF(L23=$E23,1,0)) | N23: 1 | O23: =IF($E23="","",IF(N23=$E23,1,0))
A24: 46190 | B24: K | C24: Portugal | D24: Congo DR | E24: ='Master Score'!G22 | F24: 1 | G24: =IF($E24="","",IF(F24=$E24,1,0)) | H24: 1 | I24: =IF($E24="","",IF(H24=$E24,1,0)) | J24: 1 | K24: =IF($E24="","",IF(J24=$E24,1,0)) | L24: 1 | M24: =IF($E24="","",IF(L24=$E24,1,0)) | N24: 1 | O24: =IF($E24="","",IF(N24=$E24,1,0))
A25: 46190 | B25: L | C25: England | D25: Croatia | E25: ='Master Score'!G23 | F25: X | G25: =IF($E25="","",IF(F25=$E25,1,0)) | H25: 1 | I25: =IF($E25="","",IF(H25=$E25,1,0)) | J25: 1 | K25: =IF($E25="","",IF(J25=$E25,1,0)) | L25: X | M25: =IF($E25="","",IF(L25=$E25,1,0)) | N25: 1 | O25: =IF($E25="","",IF(N25=$E25,1,0))
A26: 46191 | B26: K | C26: Uzbekistan | D26: Colombia | E26: ='Master Score'!G24 | F26: 2 | G26: =IF($E26="","",IF(F26=$E26,1,0)) | H26: 2 | I26: =IF($E26="","",IF(H26=$E26,1,0)) | J26: 2 | K26: =IF($E26="","",IF(J26=$E26,1,0)) | L26: 2 | M26: =IF($E26="","",IF(L26=$E26,1,0)) | N26: 2 | O26: =IF($E26="","",IF(N26=$E26,1,0))
A27: 46191 | B27: L | C27: Ghana | D27: Panama | E27: ='Master Score'!G25 | F27: 1 | G27: =IF($E27="","",IF(F27=$E27,1,0)) | H27: 1 | I27: =IF($E27="","",IF(H27=$E27,1,0)) | J27: X | K27: =IF($E27="","",IF(J27=$E27,1,0)) | L27: X | M27: =IF($E27="","",IF(L27=$E27,1,0)) | N27: 1 | O27: =IF($E27="","",IF(N27=$E27,1,0))
A28: 46191 | B28: A | C28: Czechia | D28: South Africa | E28: ='Master Score'!G26 | F28: X | G28: =IF($E28="","",IF(F28=$E28,1,0)) | H28: 1 | I28: =IF($E28="","",IF(H28=$E28,1,0)) | J28: 1 | K28: =IF($E28="","",IF(J28=$E28,1,0)) | L28: 1 | M28: =IF($E28="","",IF(L28=$E28,1,0)) | N28: 1 | O28: =IF($E28="","",IF(N28=$E28,1,0))
A29: 46191 | B29: B | C29: Switzerland | D29: Bosnia and Herzegovina | E29: ='Master Score'!G27 | F29: 1 | G29: =IF($E29="","",IF(F29=$E29,1,0)) | H29: 1 | I29: =IF($E29="","",IF(H29=$E29,1,0)) | J29: 1 | K29: =IF($E29="","",IF(J29=$E29,1,0)) | L29: 1 | M29: =IF($E29="","",IF(L29=$E29,1,0)) | N29: 1 | O29: =IF($E29="","",IF(N29=$E29,1,0)) | Q29: Mexico
A30: 46191 | B30: B | C30: Canada | D30: Qatar | E30: ='Master Score'!G28 | F30: 1 | G30: =IF($E30="","",IF(F30=$E30,1,0)) | H30: 1 | I30: =IF($E30="","",IF(H30=$E30,1,0)) | J30: 1 | K30: =IF($E30="","",IF(J30=$E30,1,0)) | L30: 1 | M30: =IF($E30="","",IF(L30=$E30,1,0)) | N30: 1 | O30: =IF($E30="","",IF(N30=$E30,1,0)) | Q30: Czechia
A31: 46192 | B31: A | C31: Mexico | D31: South Korea | E31: ='Master Score'!G29 | F31: 1 | G31: =IF($E31="","",IF(F31=$E31,1,0)) | H31: 1 | I31: =IF($E31="","",IF(H31=$E31,1,0)) | J31: X | K31: =IF($E31="","",IF(J31=$E31,1,0)) | L31: 1 | M31: =IF($E31="","",IF(L31=$E31,1,0)) | N31: 1 | O31: =IF($E31="","",IF(N31=$E31,1,0)) | Q31: South Korea
A32: 46192 | B32: C | C32: Scotland | D32: Morocco | E32: ='Master Score'!G30 | F32: X | G32: =IF($E32="","",IF(F32=$E32,1,0)) | H32: 2 | I32: =IF($E32="","",IF(H32=$E32,1,0)) | J32: 2 | K32: =IF($E32="","",IF(J32=$E32,1,0)) | L32: 2 | M32: =IF($E32="","",IF(L32=$E32,1,0)) | N32: 2 | O32: =IF($E32="","",IF(N32=$E32,1,0)) | Q32: South Africa
A33: 46192 | B33: D | C33: USA | D33: Australia | E33: ='Master Score'!G31 | F33: X | G33: =IF($E33="","",IF(F33=$E33,1,0)) | H33: 1 | I33: =IF($E33="","",IF(H33=$E33,1,0)) | J33: X | K33: =IF($E33="","",IF(J33=$E33,1,0)) | L33: 1 | M33: =IF($E33="","",IF(L33=$E33,1,0)) | N33: 1 | O33: =IF($E33="","",IF(N33=$E33,1,0)) | Q33: Bosnia and Herzegovina
A34: 46193 | B34: C | C34: Brazil | D34: Haiti | E34: ='Master Score'!G32 | F34: 1 | G34: =IF($E34="","",IF(F34=$E34,1,0)) | H34: 1 | I34: =IF($E34="","",IF(H34=$E34,1,0)) | J34: 1 | K34: =IF($E34="","",IF(J34=$E34,1,0)) | L34: 1 | M34: =IF($E34="","",IF(L34=$E34,1,0)) | N34: 1 | O34: =IF($E34="","",IF(N34=$E34,1,0)) | Q34: Qatar
A35: 46193 | B35: D | C35: Türkiye | D35: Paraguay | E35: ='Master Score'!G33 | F35: 1 | G35: =IF($E35="","",IF(F35=$E35,1,0)) | H35: X | I35: =IF($E35="","",IF(H35=$E35,1,0)) | J35: 1 | K35: =IF($E35="","",IF(J35=$E35,1,0)) | L35: 1 | M35: =IF($E35="","",IF(L35=$E35,1,0)) | N35: 1 | O35: =IF($E35="","",IF(N35=$E35,1,0)) | Q35: Switzerland
A36: 46193 | B36: E | C36: Germany | D36: Côte d'Ivoire | E36: ='Master Score'!G34 | F36: 1 | G36: =IF($E36="","",IF(F36=$E36,1,0)) | H36: 1 | I36: =IF($E36="","",IF(H36=$E36,1,0)) | J36: 1 | K36: =IF($E36="","",IF(J36=$E36,1,0)) | L36: 1 | M36: =IF($E36="","",IF(L36=$E36,1,0)) | N36: 1 | O36: =IF($E36="","",IF(N36=$E36,1,0)) | Q36: Canada
A37: 46193 | B37: F | C37: Netherlands | D37: Sweden | E37: ='Master Score'!G35 | F37: 1 | G37: =IF($E37="","",IF(F37=$E37,1,0)) | H37: 1 | I37: =IF($E37="","",IF(H37=$E37,1,0)) | J37: 1 | K37: =IF($E37="","",IF(J37=$E37,1,0)) | L37: 1 | M37: =IF($E37="","",IF(L37=$E37,1,0)) | N37: 1 | O37: =IF($E37="","",IF(N37=$E37,1,0)) | Q37: Brazil
A38: 46194 | B38: E | C38: Ecuador | D38: Curaçao | E38: ='Master Score'!G36 | F38: X | G38: =IF($E38="","",IF(F38=$E38,1,0)) | H38: 1 | I38: =IF($E38="","",IF(H38=$E38,1,0)) | J38: 1 | K38: =IF($E38="","",IF(J38=$E38,1,0)) | L38: 1 | M38: =IF($E38="","",IF(L38=$E38,1,0)) | N38: 1 | O38: =IF($E38="","",IF(N38=$E38,1,0)) | Q38: Haiti
A39: 46194 | B39: F | C39: Tunisia | D39: Japan | E39: ='Master Score'!G37 | F39: 2 | G39: =IF($E39="","",IF(F39=$E39,1,0)) | H39: 2 | I39: =IF($E39="","",IF(H39=$E39,1,0)) | J39: 2 | K39: =IF($E39="","",IF(J39=$E39,1,0)) | L39: 2 | M39: =IF($E39="","",IF(L39=$E39,1,0)) | N39: 2 | O39: =IF($E39="","",IF(N39=$E39,1,0)) | Q39: Morocco
A40: 46194 | B40: G | C40: Belgium | D40: IR Iran | E40: ='Master Score'!G38 | F40: X | G40: =IF($E40="","",IF(F40=$E40,1,0)) | H40: X | I40: =IF($E40="","",IF(H40=$E40,1,0)) | J40: 1 | K40: =IF($E40="","",IF(J40=$E40,1,0)) | L40: 1 | M40: =IF($E40="","",IF(L40=$E40,1,0)) | N40: 1 | O40: =IF($E40="","",IF(N40=$E40,1,0)) | Q40: Scotland
...

Sheet Leaderboard
A1: emailaddress | C1: Full Name | D1: First Name | E1: Surname | F1: Match Points | G1: Group Placement Points | H1: Total Points | I1: Tiebreaker | J1: Paid | K1: Accuracy | L1: Rank | M1: Name | N1: Points | P1: Games Played | Q1: Games Remaining | R1: Goals Scored | S1: =COUNTA(A2:B6) -> 5
A2: maob6302@gmail.com | C2: Matthew O'Brien | D2: {=_xlfn.TEXTSPLIT(C2," ")} -> Matthew | E2: O'Brien | F2: =Predictions!F3 -> 2 | G2: =Predictions!G3 -> 19 | H2: =SUM(F2:G2) -> 21 | I2: 270 | J2: TRUE | K2: =Stats!D2 -> 0.66666667 | L2: 1st | M2: {=IFERROR(INDEX(_xlfn.SORTBY($C$2:$C$6,$F$2:$F$6,-1),1),"")} -> Matthew O'Brien | N2: =IFERROR(_xlfn.XLOOKUP(M2,$C$2:$C$6,$F$2:$F$6),"") -> 2 | P2: =Stats!B2 -> 3 | Q2: =72-P2 -> 69 | R2: ='Master Score'!H74 -> 7
A3: Aarontwiss5@gmail.com | C3: Aaron Twiss | D3: {=IFERROR(_xlfn.TEXTSPLIT(C3," "),"")} -> Aaron | E3: Twiss | F3: =Predictions!H3 -> 2 | G3: =Predictions!I3 -> 12 | H3: =SUM(F3:G3) -> 14 | I3: 180 | J3: TRUE | K3: =Stats!D3 -> 0.66666667 | L3: 2nd | M3: {=IFERROR(INDEX(_xlfn.SORTBY($C$2:$C$6,$F$2:$F$6,-1),2),"")} -> Aaron Twiss | N3: =IFERROR(_xlfn.XLOOKUP(M3,$C$2:$C$6,$F$2:$F$6),"") -> 2
A4: arionaliu8@gmail.com | C4: Arion Aliu | D4: {=IFERROR(_xlfn.TEXTSPLIT(C4," "),"")} -> Arion | E4: Aliu | F4: =Predictions!J3 -> 2 | G4: =Predictions!K3 -> 19 | H4: =SUM(F4:G4) -> 21 | I4: 168 | J4: TRUE | K4: =Stats!D4 -> 0.66666667 | L4: 3rd | M4: {=IFERROR(INDEX(_xlfn.SORTBY($C$2:$C$6,$F$2:$F$6,-1),3),"")} -> Arion Aliu | N4: =IFERROR(_xlfn.XLOOKUP(M4,$C$2:$C$6,$F$2:$F$6),"") -> 2
A5: rayanzaibag18@gmail.com | C5: Rayan Zaibag | D5: {=IFERROR(_xlfn.TEXTSPLIT(C5," "),"")} -> Rayan | E5: Zaibag | F5: =Predictions!L3 -> 2 | G5: =Predictions!M3 -> 19 | H5: =SUM(F5:G5) -> 21 | I5: 180 | J5: TRUE | K5: =Stats!D5 -> 0.66666667 | L5: 4th | M5: {=IFERROR(INDEX(_xlfn.SORTBY($C$2:$C$6,$F$2:$F$6,-1),4),"")} -> Rayan Zaibag | N5: =IFERROR(_xlfn.XLOOKUP(M5,$C$2:$C$6,$F$2:$F$6),"") -> 2
A6: jorgecamarena79@gmail.com | C6: Jorge Lopez | D6: {=IFERROR(_xlfn.TEXTSPLIT(C6," "),"")} -> Jorge | E6: Lopez | F6: =Predictions!N3 -> 2 | G6: =Predictions!O3 -> 13 | H6: =SUM(F6:G6) -> 15 | I6: 197 | J6: TRUE | K6: =Stats!D6 -> 0.66666667 | L6: 5th | M6: {=IFERROR(INDEX(_xlfn.SORTBY($C$2:$C$6,$F$2:$F$6,-1),5),"")} -> Jorge Lopez | N6: =IFERROR(_xlfn.XLOOKUP(M6,$C$2:$C$6,$F$2:$F$6),"") -> 2

Sheet Stats
A1: Player | B1: Matches Played | C1: Correct Predictions | D1: Accuracy % | E1: Points Per Match | F1: Consistency (StDev) | G1: Variance | H1: Weight | I1: Z-Score | J1: Risk Rating | K1: Player Reliability Index | L1: Contrarian % | M1: Date | N1: Group | O1: Home | P1: Away | Q1: 1 | R1: 2 | S1: X | T1: Consensus Result | U1: =Predictions!F1 -> Matthew O'Brien | V1: =Predictions!H1 -> Aaron Twiss | W1: =IF(Predictions!J1=0,"",Predictions!J1) -> Arion Aliu | X1: =Predictions!L1 -> Rayan Zaibag | Y1: =Predictions!N1 -> Jorge Lopez
A2: =IF(Leaderboard!C2="","",Leaderboard!C2) -> Matthew O'Brien | B2: =COUNT('Master Score'!$G$2:$G$73)+COUNTIF('Master Score'!$G$2:$G$73,"X") -> 3 | C2: =Leaderboard!F2 -> 2 | D2: =IF(B2>0,C2/B2,0) -> 0.66666667 | E2: =IF(B2>0,C2/B2,0) -> 0.66666667 | F2: {=IF(A2="","",IFERROR(_xlfn.STDEV.P(IF(Predictions!F$4:F$75<>"",IF(Predictions!F$4:F$75='Master Score'!$G$2:$G$73,1,0))),0))} -> 0.16433555 | G2: =IF(A2="","",IFERROR(F2^2,0)) -> 0.027006173 | H2: {=IF(A2="","",IFERROR((D2/(1+G2))/SUMPRODUCT(($A$2:$A$20<>"")*($D$2:$D$20/(1+$G$2:$G$20))),0))} -> 0.2 | I2: {=IF(A2="","",IFERROR((D2-AVERAGEIF($A$2:$A$20,"<>",$D$2:$D$20))/_xlfn.STDEV.P(IF($A$2:$A$20<>"",$D$2:$D$20)),0))} -> 0 | J2: =IF(A2="","",ROUND((L2*25)+((1-D2)*30)+(G2*25)+((1-MIN(1,MAX(0,(I2+2)/4)))*20),1)) -> 34.2 | K2: =IF(A2="","",IFERROR(D2*100*(1-F2),0)) -> 55.710963 | L2: {=IF(A2="","",IFERROR(SUMPRODUCT((U$2:U$73<>"")*1*(U$2:U$73<>_xlfn.MODE.SNGL(U$2:Y$73)))/COUNTA(U$2:U$73),0))} -> 0.54166667 | M2: 46184 | N2: A | O2: Mexico | P2: South Africa | Q2: =IFERROR(COUNTIF(U2:Y2,1)/(COUNT(U2:Y2)+COUNTIF(U2:Y2,"X")),0) -> 1 | R2: =IFERROR(COUNTIF(U2:Y2,2)/(COUNT(U2:Y2)+COUNTIF(U2:Y2,"X")),0) -> 0 | S2: =IFERROR(COUNTIF(U2:Y2,"X")/(COUNT(U2:Y2)+COUNTIF(U2:Y2,"X")),0) -> 0 | T2: =IF(_xlfn.XLOOKUP(MAX(Q2:S2),Q2:S2,$Q$1:$S$1)='Master Score'!G2,1,0) -> 1 | U2: {=Predictions!F4:F75} -> 1 | V2: {=Predictions!H4:H75} -> 1 | W2: {=IF(Predictions!J4:J75=0,"",Predictions!J4:J75)} -> 1 | X2: {=IF(Predictions!L4:L75=0,"",Predictions!L4:L75)} -> 1 | Y2: {=IF(Predictions!N4:N75="","",Predictions!N4:N75)} -> 1 | AV2: {=IF(Predictions!P4:P75="","",Predictions!P4:P75)} | AW2: {=IF(Predictions!Q4:Q28="","",Predictions!Q4:Q28)} | AX2: {=IF(Predictions!R4:R75="","",Predictions!R4:R75)} | AY2: {=IF(Predictions!S4:S75="","",Predictions!S4:S75)} | AZ2: {=IF(Predictions!T4:T75="","",Predictions!T4:T75)} | BA2: {=IF(Predictions!U4:U75="","",Predictions!U4:U75)} | BB2: {=IF(Predictions!V4:V75="","",Predictions!V4:V75)} | BC2: {=IF(Predictions!W4:W75="","",Predictions!W4:W75)} | BD2: {=IF(Predictions!X4:X75="","",Predictions!X4:X75)} | BE2: {=IF(Predictions!Y4:Y75="","",Predictions!Y4:Y75)} | ... BM2: {=IF(Predictions!AG4:AG75="","",Predictions!AG4:AG75)}
A3: =IF(Leaderboard!C3="","",Leaderboard!C3) -> Aaron Twiss | B3: =COUNT('Master Score'!$G$2:$G$73)+COUNTIF('Master Score'!$G$2:$G$73,"X") -> 3 | C3: =Leaderboard!F3 -> 2 | D3: =IFERROR(C3/B3,0) -> 0.66666667 | E3: =IFERROR(C3/B3,0) -> 0.66666667 | F3: {=IF(A3="","",IFERROR(_xlfn.STDEV.P(IF(Predictions!H$4:H$75<>"",IF(Predictions!H$4:H$75='Master Score'!$G$2:$G$73,1,0))),0))} -> 0.16433555 | G3: =IF(A3="","",IFERROR(F3^2,0)) -> 0.027006173 | H3: {=IF(A3="","",IFERROR((D3/(1+G3))/SUMPRODUCT(($A$2:$A$20<>"")*($D$2:$D$20/(1+$G$2:$G$20))),0))} -> 0.2 | I3: {=IF(A3="","",IFERROR((D3-AVERAGEIF($A$2:$A$20,"<>",$D$2:$D$20))/_xlfn.STDEV.P(IF($A$2:$A$20<>"",$D$2:$D$20)),0))} -> 0 | J3: =IF(A3="","",ROUND((L3*25)+((1-D3)*30)+(G3*25)+((1-MIN(1,MAX(0,(I3+2)/4)))*20),1)) -> 33.9 | K3: =IF(A3="","",IFERROR(D3*100*(1-F3),0)) -> 55.710963 | L3: {=IF(A3="","",IFERROR(SUMPRODUCT((V$2:V$73<>"")*1*(V$2:V$73<>_xlfn.MODE.SNGL(U$2:Y$73)))/COUNTA(V$2:V$73),0))} -> 0.52777778 | M3: 46185 | N3: A | O3: South Korea | P3: Czechia | Q3: =IFERROR(COUNTIF(U3:Y3,1)/(COUNT(U3:Y3)+COUNTIF(U3:Y3,"X")),0) -> 0.6 | R3: =IFERROR(COUNTIF(U3:Y3,2)/(COUNT(U3:Y3)+COUNTIF(U3:Y3,"X")),0) -> 0 | S3: =IFERROR(COUNTIF(U3:Y3,"X")/(COUNT(U3:Y3)+COUNTIF(U3:Y3,"X")),0) -> 0.4 | T3: =IF(_xlfn.XLOOKUP(MAX(Q3:S3),Q3:S3,$Q$1:$S$1)='Master Score'!G3,1,0) -> 1 | U3: 1 | V3: X | W3: 1 | X3: X | Y3: 1
A4: =IF(Leaderboard!C4="","",Leaderboard!C4) -> Arion Aliu | B4: =COUNT('Master Score'!$G$2:$G$73)+COUNTIF('Master Score'!$G$2:$G$73,"X") -> 3 | C4: =Leaderboard!F4 -> 2 | D4: =IFERROR(C4/B4,0) -> 0.66666667 | E4: =IFERROR(C4/B4,0) -> 0.66666667 | F4: {=IF(A4="","",IFERROR(_xlfn.STDEV.P(IF(Predictions!J$4:J$75<>"",IF(Predictions!J$4:J$75='Master Score'!$G$2:$G$73,1,0))),0))} -> 0.16433555 | G4: =IF(A4="","",IFERROR(F4^2,0)) -> 0.027006173 | H4: {=IF(A4="","",IFERROR((D4/(1+G4))/SUMPRODUCT(($A$2:$A$20<>"")*($D$2:$D$20/(1+$G$2:$G$20))),0))} -> 0.2 | I4: {=IF(A4="","",IFERROR((D4-AVERAGEIF($A$2:$A$20,"<>",$D$2:$D$20))/_xlfn.STDEV.P(IF($A$2:$A$20<>"",$D$2:$D$20)),0))} -> 0 | J4: =IF(A4="","",ROUND((L4*25)+((1-D4)*30)+(G4*25)+((1-MIN(1,MAX(0,(I4+2)/4)))*20),1)) -> 32.8 | K4: =IF(A4="","",IFERROR(D4*100*(1-F4),0)) -> 55.710963 | L4: {=IF(A4="","",IFERROR(SUMPRODUCT((W$2:W$73<>"")*1*(W$2:W$73<>_xlfn.MODE.SNGL(U$2:Y$73)))/COUNTA(W$2:W$73),0))} -> 0.48611111 | M4: 46185 | N4: B | O4: Canada | P4: Bosnia and Herzegovina | Q4: =IFERROR(COUNTIF(U4:Y4,1)/(COUNT(U4:Y4)+COUNTIF(U4:Y4,"X")),0) -> 0.4 | R4: =IFERROR(COUNTIF(U4:Y4,2)/(COUNT(U4:Y4)+COUNTIF(U4:Y4,"X")),0) -> 0.2 | S4: =IFERROR(COUNTIF(U4:Y4,"X")/(COUNT(U4:Y4)+COUNTIF(U4:Y4,"X")),0) -> 0.4 | T4: =IF(_xlfn.XLOOKUP(MAX(Q4:S4),Q4:S4,$Q$1:$S$1)='Master Score'!G4,1,0) -> 0 | U4: 1 | V4: X | W4: 2 | X4: X | Y4: 1
A5: =IF(Leaderboard!C5="","",Leaderboard!C5) -> Rayan Zaibag | B5: =COUNT('Master Score'!$G$2:$G$73)+COUNTIF('Master Score'!$G$2:$G$73,"X") -> 3 | C5: =Leaderboard!F5 -> 2 | D5: =IFERROR(C5/B5,0) -> 0.66666667 | E5: =IFERROR(C5/B5,0) -> 0.66666667 | F5: {=IF(A5="","",IFERROR(_xlfn.STDEV.P(IF(Predictions!L$4:L$75<>"",IF(Predictions!L$4:L$75='Master Score'!$G$2:$G$73,1,0))),0))} -> 0.16433555 | G5: =IF(A5="","",IFERROR(F5^2,0)) -> 0.027006173 | H5: {=IF(A5="","",IFERROR((D5/(1+G5))/SUMPRODUCT(($A$2:$A$20<>"")*($D$2:$D$20/(1+$G$2:$G$20))),0))} -> 0.2 | I5: {=IF(A5="","",IFERROR((D5-AVERAGEIF($A$2:$A$20,"<>",$D$2:$D$20))/_xlfn.STDEV.P(IF($A$2:$A$20<>"",$D$2:$D$20)),0))} -> 0 | J5: =IF(A5="","",ROUND((L5*25)+((1-D5)*30)+(G5*25)+((1-MIN(1,MAX(0,(I5+2)/4)))*20),1)) -> 32.5 | K5: =IF(A5="","",IFERROR(D5*100*(1-F5),0)) -> 55.710963 | L5: {=IF(A5="","",IFERROR(SUMPRODUCT((X$2:X$73<>"")*1*(X$2:X$73<>_xlfn.MODE.SNGL(U$2:Y$73)))/COUNTA(X$2:X$73),0))} -> 0.47222222 | M5: 46186 | N5: D | O5: USA | P5: Paraguay | Q5: =IFERROR(COUNTIF(U5:Y5,1)/(COUNT(U5:Y5)+COUNTIF(U5:Y5,"X")),0) -> 0.8 | R5: =IFERROR(COUNTIF(U5:Y5,2)/(COUNT(U5:Y5)+COUNTIF(U5:Y5,"X")),0) -> 0.2 | S5: =IFERROR(COUNTIF(U5:Y5,"X")/(COUNT(U5:Y5)+COUNTIF(U5:Y5,"X")),0) -> 0 | T5: =IF(_xlfn.XLOOKUP(MAX(Q5:S5),Q5:S5,$Q$1:$S$1)='Master Score'!G5,1,0) -> 0 | U5: 1 | V5: 2 | W5: 1 | X5: 1 | Y5: 1
A6: =IF(Leaderboard!C6="","",Leaderboard!C6) -> Jorge Lopez | B6: =COUNT('Master Score'!$G$2:$G$73)+COUNTIF('Master Score'!$G$2:$G$73,"X") -> 3 | C6: =Leaderboard!F6 -> 2 | D6: =IFERROR(C6/B6,0) -> 0.66666667 | E6: =IFERROR(C6/B6,0) -> 0.66666667 | F6: {=IF(A6="","",IFERROR(_xlfn.STDEV.P(IF(Predictions!N$4:N$75<>"",IF(Predictions!N$4:N$75='Master Score'!$G$2:$G$73,1,0))),0))} -> 0.16433555 | G6: =IF(A6="","",IFERROR(F6^2,0)) -> 0.027006173 | H6: {=IF(A6="","",IFERROR((D6/(1+G6))/SUMPRODUCT(($A$2:$A$20<>"")*($D$2:$D$20/(1+$G$2:$G$20))),0))} -> 0.2 | I6: {=IF(A6="","",IFERROR((D6-AVERAGEIF($A$2:$A$20,"<>",$D$2:$D$20))/_xlfn.STDEV.P(IF($A$2:$A$20<>"",$D$2:$D$20)),0))} -> 0 | J6: =IF(A6="","",ROUND((L6*25)+((1-D6)*30)+(G6*25)+((1-MIN(1,MAX(0,(I6+2)/4)))*20),1)) -> 31.8 | K6: =IF(A6="","",IFERROR(D6*100*(1-F6),0)) -> 55.710963 | L6: {=IF(A6="","",IFERROR(SUMPRODUCT((Y$2:Y$73<>"")*1*(Y$2:Y$73<>_xlfn.MODE.SNGL(U$2:Y$73)))/COUNTA(Y$2:Y$73),0))} -> 0.44444444 | M6: 46186 | N6: B | O6: Qatar | P6: Switzerland | Q6: =IFERROR(COUNTIF(U6:Y6,1)/(COUNT(U6:Y6)+COUNTIF(U6:Y6,"X")),0) -> 0 | R6: =IFERROR(COUNTIF(U6:Y6,2)/(COUNT(U6:Y6)+COUNTIF(U6:Y6,"X")),0) -> 1 | S6: =IFERROR(COUNTIF(U6:Y6,"X")/(COUNT(U6:Y6)+COUNTIF(U6:Y6,"X")),0) -> 0 | T6: =IF(_xlfn.XLOOKUP(MAX(Q6:S6),Q6:S6,$Q$1:$S$1)='Master Score'!G6,1,0) -> 0 | U6: 2 | V6: 2 | W6: 2 | X6: 2 | Y6: 2
M7: 46186 | N7: C | O7: Brazil | P7: Morocco | Q7: =IFERROR(COUNTIF(U7:Y7,1)/(COUNT(U7:Y7)+COUNTIF(U7:Y7,"X")),0) -> 0.8 | R7: =IFERROR(COUNTIF(U7:Y7,2)/(COUNT(U7:Y7)+COUNTIF(U7:Y7,"X")),0) -> 0.2 | S7: =IFERROR(COUNTIF(U7:Y7,"X")/(COUNT(U7:Y7)+COUNTIF(U7:Y7,"X")),0) -> 0 | T7: =IF(_xlfn.XLOOKUP(MAX(Q7:S7),Q7:S7,$Q$1:$S$1)='Master Score'!G7,1,0) -> 0 | U7: 1 | V7: 2 | W7: 1 | X7: 1 | Y7: 1
M8: 46187 | N8: C | O8: Haiti | P8: Scotland | Q8: =IFERROR(COUNTIF(U8:Y8,1)/(COUNT(U8:Y8)+COUNTIF(U8:Y8,"X")),0) -> 0 | R8: =IFERROR(COUNTIF(U8:Y8,2)/(COUNT(U8:Y8)+COUNTIF(U8:Y8,"X")),0) -> 1 | S8: =IFERROR(COUNTIF(U8:Y8,"X")/(COUNT(U8:Y8)+COUNTIF(U8:Y8,"X")),0) -> 0 | T8: =IF(_xlfn.XLOOKUP(MAX(Q8:S8),Q8:S8,$Q$1:$S$1)='Master Score'!G8,1,0) -> 0 | U8: 2 | V8: 2 | W8: 2 | X8: 2 | Y8: 2
M9: 46187 | N9: D | O9: Australia | P9: Türkiye | Q9: =IFERROR(COUNTIF(U9:Y9,1)/(COUNT(U9:Y9)+COUNTIF(U9:Y9,"X")),0) -> 0 | R9: =IFERROR(COUNTIF(U9:Y9,2)/(COUNT(U9:Y9)+COUNTIF(U9:Y9,"X")),0) -> 1 | S9: =IFERROR(COUNTIF(U9:Y9,"X")/(COUNT(U9:Y9)+COUNTIF(U9:Y9,"X")),0) -> 0 | T9: =IF(_xlfn.XLOOKUP(MAX(Q9:S9),Q9:S9,$Q$1:$S$1)='Master Score'!G9,1,0) -> 0 | U9: 2 | V9: 2 | W9: 2 | X9: 2 | Y9: 2
M10: 46187 | N10: E | O10: Germany | P10: Curaçao | Q10: =IFERROR(COUNTIF(U10:Y10,1)/(COUNT(U10:Y10)+COUNTIF(U10:Y10,"X")),0) -> 1 | R10: =IFERROR(COUNTIF(U10:Y10,2)/(COUNT(U10:Y10)+COUNTIF(U10:Y10,"X")),0) -> 0 | S10: =IFERROR(COUNTIF(U10:Y10,"X")/(COUNT(U10:Y10)+COUNTIF(U10:Y10,"X")),0) -> 0 | T10: =IF(_xlfn.XLOOKUP(MAX(Q10:S10),Q10:S10,$Q$1:$S$1)='Master Score'!G10,1,0) -> 0 | U10: 1 | V10: 1 | W10: 1 | X10: 1 | Y10: 1
M11: 46187 | N11: F | O11: Netherlands | P11: Japan | Q11: =IFERROR(COUNTIF(U11:Y11,1)/(COUNT(U11:Y11)+COUNTIF(U11:Y11,"X")),0) -> 0.4 | R11: =IFERROR(COUNTIF(U11:Y11,2)/(COUNT(U11:Y11)+COUNTIF(U11:Y11,"X")),0) -> 0 | S11: =IFERROR(COUNTIF(U11:Y11,"X")/(COUNT(U11:Y11)+COUNTIF(U11:Y11,"X")),0) -> 0.6 | T11: =IF(_xlfn.XLOOKUP(MAX(Q11:S11),Q11:S11,$Q$1:$S$1)='Master Score'!G11,1,0) -> 0 | U11: X | V11: 1 | W11: 1 | X11: X | Y11: X
M12: 46188 | N12: E | O12: Côte d'Ivoire | P12: Ecuador | Q12: =IFERROR(COUNTIF(U12:Y12,1)/(COUNT(U12:Y12)+COUNTIF(U12:Y12,"X")),0) -> 0.4 | R12: =IFERROR(COUNTIF(U12:Y12,2)/(COUNT(U12:Y12)+COUNTIF(U12:Y12,"X")),0) -> 0.2 | S12: =IFERROR(COUNTIF(U12:Y12,"X")/(COUNT(U12:Y12)+COUNTIF(U12:Y12,"X")),0) -> 0.4 | T12: =IF(_xlfn.XLOOKUP(MAX(Q12:S12),Q12:S12,$Q$1:$S$1)='Master Score'!G12,1,0) -> 0 | U12: 1 | V12: X | W12: 1 | X12: X | Y12: 2
M13: 46188 | N13: F | O13: Sweden | P13: Tunisia | Q13: =IFERROR(COUNTIF(U13:Y13,1)/(COUNT(U13:Y13)+COUNTIF(U13:Y13,"X")),0) -> 0.6 | R13: =IFERROR(COUNTIF(U13:Y13,2)/(COUNT(U13:Y13)+COUNTIF(U13:Y13,"X")),0) -> 0.2 | S13: =IFERROR(COUNTIF(U13:Y13,"X")/(COUNT(U13:Y13)+COUNTIF(U13:Y13,"X")),0) -> 0.2 | T13: =IF(_xlfn.XLOOKUP(MAX(Q13:S13),Q13:S13,$Q$1:$S$1)='Master Score'!G13,1,0) -> 0 | U13: 1 | V13: X | W13: 1 | X13: 1 | Y13: 2
M14: 46188 | N14: G | O14: Belgium | P14: Egypt | Q14: =IFERROR(COUNTIF(U14:Y14,1)/(COUNT(U14:Y14)+COUNTIF(U14:Y14,"X")),0) -> 1 | R14: =IFERROR(COUNTIF(U14:Y14,2)/(COUNT(U14:Y14)+COUNTIF(U14:Y14,"X")),0) -> 0 | S14: =IFERROR(COUNTIF(U14:Y14,"X")/(COUNT(U14:Y14)+COUNTIF(U14:Y14,"X")),0) -> 0 | T14: =IF(_xlfn.XLOOKUP(MAX(Q14:S14),Q14:S14,$Q$1:$S$1)='Master Score'!G14,1,0) -> 0 | U14: 1 | V14: 1 | W14: 1 | X14: 1 | Y14: 1
M15: 46188 | N15: H | O15: Spain | P15: Cabo Verde | Q15: =IFERROR(COUNTIF(U15:Y15,1)/(COUNT(U15:Y15)+COUNTIF(U15:Y15,"X")),0) -> 1 | R15: =IFERROR(COUNTIF(U15:Y15,2)/(COUNT(U15:Y15)+COUNTIF(U15:Y15,"X")),0) -> 0 | S15: =IFERROR(COUNTIF(U15:Y15,"X")/(COUNT(U15:Y15)+COUNTIF(U15:Y15,"X")),0) -> 0 | T15: =IF(_xlfn.XLOOKUP(MAX(Q15:S15),Q15:S15,$Q$1:$S$1)='Master Score'!G15,1,0) -> 0 | U15: 1 | V15: 1 | W15: 1 | X15: 1 | Y15: 1
M16: 46188 | N16: H | O16: Saudi Arabia | P16: Uruguay | Q16: =IFERROR(COUNTIF(U16:Y16,1)/(COUNT(U16:Y16)+COUNTIF(U16:Y16,"X")),0) -> 0 | R16: =IFERROR(COUNTIF(U16:Y16,2)/(COUNT(U16:Y16)+COUNTIF(U16:Y16,"X")),0) -> 1 | S16: =IFERROR(COUNTIF(U16:Y16,"X")/(COUNT(U16:Y16)+COUNTIF(U16:Y16,"X")),0) -> 0 | T16: =IF(_xlfn.XLOOKUP(MAX(Q16:S16),Q16:S16,$Q$1:$S$1)='Master Score'!G16,1,0) -> 0 | U16: 2 | V16: 2 | W16: 2 | X16: 2 | Y16: 2
M17: 46189 | N17: G | O17: IR Iran | P17: New Zealand | Q17: =IFERROR(COUNTIF(U17:Y17,1)/(COUNT(U17:Y17)+COUNTIF(U17:Y17,"X")),0) -> 0.6 | R17: =IFERROR(COUNTIF(U17:Y17,2)/(COUNT(U17:Y17)+COUNTIF(U17:Y17,"X")),0) -> 0.2 | S17: =IFERROR(COUNTIF(U17:Y17,"X")/(COUNT(U17:Y17)+COUNTIF(U17:Y17,"X")),0) -> 0.2 | T17: =IF(_xlfn.XLOOKUP(MAX(Q17:S17),Q17:S17,$Q$1:$S$1)='Master Score'!G17,1,0) -> 0 | U17: X | V17: 1 | W17: 2 | X17: 1 | Y17: 1
M18: 46189 | N18: I | O18: France | P18: Senegal | Q18: =IFERROR(COUNTIF(U18:Y18,1)/(COUNT(U18:Y18)+COUNTIF(U18:Y18,"X")),0) -> 1 | R18: =IFERROR(COUNTIF(U18:Y18,2)/(COUNT(U18:Y18)+COUNTIF(U18:Y18,"X")),0) -> 0 | S18: =IFERROR(COUNTIF(U18:Y18,"X")/(COUNT(U18:Y18)+COUNTIF(U18:Y18,"X")),0) -> 0 | T18: =IF(_xlfn.XLOOKUP(MAX(Q18:S18),Q18:S18,$Q$1:$S$1)='Master Score'!G18,1,0) -> 0 | U18: 1 | V18: 1 | W18: 1 | X18: 1 | Y18: 1
M19: 46189 | N19: I | O19: Iraq | P19: Norway | Q19: =IFERROR(COUNTIF(U19:Y19,1)/(COUNT(U19:Y19)+COUNTIF(U19:Y19,"X")),0) -> 0 | R19: =IFERROR(COUNTIF(U19:Y19,2)/(COUNT(U19:Y19)+COUNTIF(U19:Y19,"X")),0) -> 1 | S19: =IFERROR(COUNTIF(U19:Y19,"X")/(COUNT(U19:Y19)+COUNTIF(U19:Y19,"X")),0) -> 0 | T19: =IF(_xlfn.XLOOKUP(MAX(Q19:S19),Q19:S19,$Q$1:$S$1)='Master Score'!G19,1,0) -> 0 | U19: 2 | V19: 2 | W19: 2 | X19: 2 | Y19: 2
M20: 46190 | N20: J | O20: Argentina | P20: Algeria | Q20: =IFERROR(COUNTIF(U20:Y20,1)/(COUNT(U20:Y20)+COUNTIF(U20:Y20,"X")),0) -> 1 | R20: =IFERROR(COUNTIF(U20:Y20,2)/(COUNT(U20:Y20)+COUNTIF(U20:Y20,"X")),0) -> 0 | S20: =IFERROR(COUNTIF(U20:Y20,"X")/(COUNT(U20:Y20)+COUNTIF(U20:Y20,"X")),0) -> 0 | T20: =IF(_xlfn.XLOOKUP(MAX(Q20:S20),Q20:S20,$Q$1:$S$1)='Master Score'!G20,1,0) -> 0 | U20: 1 | V20: 1 | W20: 1 | X20: 1 | Y20: 1
M21: 46190 | N21: J | O21: Austria | P21: Jordan | Q21: =IFERROR(COUNTIF(U21:Y21,1)/(COUNT(U21:Y21)+COUNTIF(U21:Y21,"X")),0) -> 1 | R21: =IFERROR(COUNTIF(U21:Y21,2)/(COUNT(U21:Y21)+COUNTIF(U21:Y21,"X")),0) -> 0 | S21: =IFERROR(COUNTIF(U21:Y21,"X")/(COUNT(U21:Y21)+COUNTIF(U21:Y21,"X")),0) -> 0 | T21: =IF(_xlfn.XLOOKUP(MAX(Q21:S21),Q21:S21,$Q$1:$S$1)='Master Score'!G21,1,0) -> 0 | U21: 1 | V21: 1 | W21: 1 | X21: 1 | Y21: 1
M22: 46190 | N22: K | O22: Portugal | P22: Congo DR | Q22: =IFERROR(COUNTIF(U22:Y22,1)/(COUNT(U22:Y22)+COUNTIF(U22:Y22,"X")),0) -> 1 | R22: =IFERROR(COUNTIF(U22:Y22,2)/(COUNT(U22:Y22)+COUNTIF(U22:Y22,"X")),0) -> 0 | S22: =IFERROR(COUNTIF(U22:Y22,"X")/(COUNT(U22:Y22)+COUNTIF(U22:Y22,"X")),0) -> 0 | T22: =IF(_xlfn.XLOOKUP(MAX(Q22:S22),Q22:S22,$Q$1:$S$1)='Master Score'!G22,1,0) -> 0 | U22: 1 | V22: 1 | W22: 1 | X22: 1 | Y22: 1
M23: 46190 | N23: L | O23: England | P23: Croatia | Q23: =IFERROR(COUNTIF(U23:Y23,1)/(COUNT(U23:Y23)+COUNTIF(U23:Y23,"X")),0) -> 0.6 | R23: =IFERROR(COUNTIF(U23:Y23,2)/(COUNT(U23:Y23)+COUNTIF(U23:Y23,"X")),0) -> 0 | S23: =IFERROR(COUNTIF(U23:Y23,"X")/(COUNT(U23:Y23)+COUNTIF(U23:Y23,"X")),0) -> 0.4 | T23: =IF(_xlfn.XLOOKUP(MAX(Q23:S23),Q23:S23,$Q$1:$S$1)='Master Score'!G23,1,0) -> 0 | U23: X | V23: 1 | W23: 1 | X23: X | Y23: 1
M24: 46191 | N24: K | O24: Uzbekistan | P24: Colombia | Q24: =IFERROR(COUNTIF(U24:Y24,1)/(COUNT(U24:Y24)+COUNTIF(U24:Y24,"X")),0) -> 0 | R24: =IFERROR(COUNTIF(U24:Y24,2)/(COUNT(U24:Y24)+COUNTIF(U24:Y24,"X")),0) -> 1 | S24: =IFERROR(COUNTIF(U24:Y24,"X")/(COUNT(U24:Y24)+COUNTIF(U24:Y24,"X")),0) -> 0 | T24: =IF(_xlfn.XLOOKUP(MAX(Q24:S24),Q24:S24,$Q$1:$S$1)='Master Score'!G24,1,0) -> 0 | U24: 2 | V24: 2 | W24: 2 | X24: 2 | Y24: 2
M25: 46191 | N25: L | O25: Ghana | P25: Panama | Q25: =IFERROR(COUNTIF(U25:Y25,1)/(COUNT(U25:Y25)+COUNTIF(U25:Y25,"X")),0) -> 0.6 | R25: =IFERROR(COUNTIF(U25:Y25,2)/(COUNT(U25:Y25)+COUNTIF(U25:Y25,"X")),0) -> 0 | S25: =IFERROR(COUNTIF(U25:Y25,"X")/(COUNT(U25:Y25)+COUNTIF(U25:Y25,"X")),0) -> 0.4 | T25: =IF(_xlfn.XLOOKUP(MAX(Q25:S25),Q25:S25,$Q$1:$S$1)='Master Score'!G25,1,0) -> 0 | U25: 1 | V25: 1 | W25: X | X25: X | Y25: 1
M26: 46191 | N26: A | O26: Czechia | P26: South Africa | Q26: =IFERROR(COUNTIF(U26:Y26,1)/(COUNT(U26:Y26)+COUNTIF(U26:Y26,"X")),0) -> 0.8 | R26: =IFERROR(COUNTIF(U26:Y26,2)/(COUNT(U26:Y26)+COUNTIF(U26:Y26,"X")),0) -> 0 | S26: =IFERROR(COUNTIF(U26:Y26,"X")/(COUNT(U26:Y26)+COUNTIF(U26:Y26,"X")),0) -> 0.2 | T26: =IF(_xlfn.XLOOKUP(MAX(Q26:S26),Q26:S26,$Q$1:$S$1)='Master Score'!G26,1,0) -> 0 | U26: X | V26: 1 | W26: 1 | X26: 1 | Y26: 1
M27: 46191 | N27: B | O27: Switzerland | P27: Bosnia and Herzegovina | Q27: =IFERROR(COUNTIF(U27:Y27,1)/(COUNT(U27:Y27)+COUNTIF(U27:Y27,"X")),0) -> 1 | R27: =IFERROR(COUNTIF(U27:Y27,2)/(COUNT(U27:Y27)+COUNTIF(U27:Y27,"X")),0) -> 0 | S27: =IFERROR(COUNTIF(U27:Y27,"X")/(COUNT(U27:Y27)+COUNTIF(U27:Y27,"X")),0) -> 0 | T27: =IF(_xlfn.XLOOKUP(MAX(Q27:S27),Q27:S27,$Q$1:$S$1)='Master Score'!G27,1,0) -> 0 | U27: 1 | V27: 1 | W27: 1 | X27: 1 | Y27: 1
M28: 46191 | N28: B | O28: Canada | P28: Qatar | Q28: =IFERROR(COUNTIF(U28:Y28,1)/(COUNT(U28:Y28)+COUNTIF(U28:Y28,"X")),0) -> 1 | R28: =IFERROR(COUNTIF(U28:Y28,2)/(COUNT(U28:Y28)+COUNTIF(U28:Y28,"X")),0) -> 0 | S28: =IFERROR(COUNTIF(U28:Y28,"X")/(COUNT(U28:Y28)+COUNTIF(U28:Y28,"X")),0) -> 0 | T28: =IF(_xlfn.XLOOKUP(MAX(Q28:S28),Q28:S28,$Q$1:$S$1)='Master Score'!G28,1,0) -> 0 | U28: 1 | V28: 1 | W28: 1 | X28: 1 | Y28: 1
M29: 46192 | N29: A | O29: Mexico | P29: South Korea | Q29: =IFERROR(COUNTIF(U29:Y29,1)/(COUNT(U29:Y29)+COUNTIF(U29:Y29,"X")),0) -> 0.8 | R29: =IFERROR(COUNTIF(U29:Y29,2)/(COUNT(U29:Y29)+COUNTIF(U29:Y29,"X")),0) -> 0 | S29: =IFERROR(COUNTIF(U29:Y29,"X")/(COUNT(U29:Y29)+COUNTIF(U29:Y29,"X")),0) -> 0.2 | T29: =IF(_xlfn.XLOOKUP(MAX(Q29:S29),Q29:S29,$Q$1:$S$1)='Master Score'!G29,1,0) -> 0 | U29: 1 | V29: 1 | W29: X | X29: 1 | Y29: 1
M30: 46192 | N30: C | O30: Scotland | P30: Morocco | Q30: =IFERROR(COUNTIF(U30:Y30,1)/(COUNT(U30:Y30)+COUNTIF(U30:Y30,"X")),0) -> 0 | R30: =IFERROR(COUNTIF(U30:Y30,2)/(COUNT(U30:Y30)+COUNTIF(U30:Y30,"X")),0) -> 0.8 | S30: =IFERROR(COUNTIF(U30:Y30,"X")/(COUNT(U30:Y30)+COUNTIF(U30:Y30,"X")),0) -> 0.2 | T30: =IF(_xlfn.XLOOKUP(MAX(Q30:S30),Q30:S30,$Q$1:$S$1)='Master Score'!G30,1,0) -> 0 | U30: X | V30: 2 | W30: 2 | X30: 2 | Y30: 2
M31: 46192 | N31: D | O31: USA | P31: Australia | Q31: =IFERROR(COUNTIF(U31:Y31,1)/(COUNT(U31:Y31)+COUNTIF(U31:Y31,"X")),0) -> 0.6 | R31: =IFERROR(COUNTIF(U31:Y31,2)/(COUNT(U31:Y31)+COUNTIF(U31:Y31,"X")),0) -> 0 | S31: =IFERROR(COUNTIF(U31:Y31,"X")/(COUNT(U31:Y31)+COUNTIF(U31:Y31,"X")),0) -> 0.4 | T31: =IF(_xlfn.XLOOKUP(MAX(Q31:S31),Q31:S31,$Q$1:$S$1)='Master Score'!G31,1,0) -> 0 | U31: X | V31: 1 | W31: X | X31: 1 | Y31: 1
M32: 46193 | N32: C | O32: Brazil | P32: Haiti | Q32: =IFERROR(COUNTIF(U32:Y32,1)/(COUNT(U32:Y32)+COUNTIF(U32:Y32,"X")),0) -> 1 | R32: =IFERROR(COUNTIF(U32:Y32,2)/(COUNT(U32:Y32)+COUNTIF(U32:Y32,"X")),0) -> 0 | S32: =IFERROR(COUNTIF(U32:Y32,"X")/(COUNT(U32:Y32)+COUNTIF(U32:Y32,"X")),0) -> 0 | T32: =IF(_xlfn.XLOOKUP(MAX(Q32:S32),Q32:S32,$Q$1:$S$1)='Master Score'!G32,1,0) -> 0 | U32: 1 | V32: 1 | W32: 1 | X32: 1 | Y32: 1
M33: 46193 | N33: D | O33: Türkiye | P33: Paraguay | Q33: =IFERROR(COUNTIF(U33:Y33,1)/(COUNT(U33:Y33)+COUNTIF(U33:Y33,"X")),0) -> 0.8 | R33: =IFERROR(COUNTIF(U33:Y33,2)/(COUNT(U33:Y33)+COUNTIF(U33:Y33,"X")),0) -> 0 | S33: =IFERROR(COUNTIF(U33:Y33,"X")/(COUNT(U33:Y33)+COUNTIF(U33:Y33,"X")),0) -> 0.2 | T33: =IF(_xlfn.XLOOKUP(MAX(Q33:S33),Q33:S33,$Q$1:$S$1)='Master Score'!G33,1,0) -> 0 | U33: 1 | V33: X | W33: 1 | X33: 1 | Y33: 1
M34: 46193 | N34: E | O34: Germany | P34: Côte d'Ivoire | Q34: =IFERROR(COUNTIF(U34:Y34,1)/(COUNT(U34:Y34)+COUNTIF(U34:Y34,"X")),0) -> 1 | R34: =IFERROR(COUNTIF(U34:Y34,2)/(COUNT(U34:Y34)+COUNTIF(U34:Y34,"X")),0) -> 0 | S34: =IFERROR(COUNTIF(U34:Y34,"X")/(COUNT(U34:Y34)+COUNTIF(U34:Y34,"X")),0) -> 0 | T34: =IF(_xlfn.XLOOKUP(MAX(Q34:S34),Q34:S34,$Q$1:$S$1)='Master Score'!G34,1,0) -> 0 | U34: 1 | V34: 1 | W34: 1 | X34: 1 | Y34: 1
M35: 46193 | N35: F | O35: Netherlands | P35: Sweden | Q35: =IFERROR(COUNTIF(U35:Y35,1)/(COUNT(U35:Y35)+COUNTIF(U35:Y35,"X")),0) -> 1 | R35: =IFERROR(COUNTIF(U35:Y35,2)/(COUNT(U35:Y35)+COUNTIF(U35:Y35,"X")),0) -> 0 | S35: =IFERROR(COUNTIF(U35:Y35,"X")/(COUNT(U35:Y35)+COUNTIF(U35:Y35,"X")),0) -> 0 | T35: =IF(_xlfn.XLOOKUP(MAX(Q35:S35),Q35:S35,$Q$1:$S$1)='Master Score'!G35,1,0) -> 0 | U35: 1 | V35: 1 | W35: 1 | X35: 1 | Y35: 1
M36: 46194 | N36: E | O36: Ecuador | P36: Curaçao | Q36: =IFERROR(COUNTIF(U36:Y36,1)/(COUNT(U36:Y36)+COUNTIF(U36:Y36,"X")),0) -> 0.8 | R36: =IFERROR(COUNTIF(U36:Y36,2)/(COUNT(U36:Y36)+COUNTIF(U36:Y36,"X")),0) -> 0 | S36: =IFERROR(COUNTIF(U36:Y36,"X")/(COUNT(U36:Y36)+COUNTIF(U36:Y36,"X")),0) -> 0.2 | T36: =IF(_xlfn.XLOOKUP(MAX(Q36:S36),Q36:S36,$Q$1:$S$1)='Master Score'!G36,1,0) -> 0 | U36: X | V36: 1 | W36: 1 | X36: 1 | Y36: 1
M37: 46194 | N37: F | O37: Tunisia | P37: Japan | Q37: =IFERROR(COUNTIF(U37:Y37,1)/(COUNT(U37:Y37)+COUNTIF(U37:Y37,"X")),0) -> 0 | R37: =IFERROR(COUNTIF(U37:Y37,2)/(COUNT(U37:Y37)+COUNTIF(U37:Y37,"X")),0) -> 1 | S37: =IFERROR(COUNTIF(U37:Y37,"X")/(COUNT(U37:Y37)+COUNTIF(U37:Y37,"X")),0) -> 0 | T37: =IF(_xlfn.XLOOKUP(MAX(Q37:S37),Q37:S37,$Q$1:$S$1)='Master Score'!G37,1,0) -> 0 | U37: 2 | V37: 2 | W37: 2 | X37: 2 | Y37: 2
M38: 46194 | N38: G | O38: Belgium | P38: IR Iran | Q38: =IFERROR(COUNTIF(U38:Y38,1)/(COUNT(U38:Y38)+COUNTIF(U38:Y38,"X")),0) -> 0.6 | R38: =IFERROR(COUNTIF(U38:Y38,2)/(COUNT(U38:Y38)+COUNTIF(U38:Y38,"X")),0) -> 0 | S38: =IFERROR(COUNTIF(U38:Y38,"X")/(COUNT(U38:Y38)+COUNTIF(U38:Y38,"X")),0) -> 0.4 | T38: =IF(_xlfn.XLOOKUP(MAX(Q38:S38),Q38:S38,$Q$1:$S$1)='Master Score'!G38,1,0) -> 0 | U38: X | V38: X | W38: 1 | X38: 1 | Y38: 1
M39: 46194 | N39: H | O39: Spain | P39: Saudi Arabia | Q39: =IFERROR(COUNTIF(U39:Y39,1)/(COUNT(U39:Y39)+COUNTIF(U39:Y39,"X")),0) -> 1 | R39: =IFERROR(COUNTIF(U39:Y39,2)/(COUNT(U39:Y39)+COUNTIF(U39:Y39,"X")),0) -> 0 | S39: =IFERROR(COUNTIF(U39:Y39,"X")/(COUNT(U39:Y39)+COUNTIF(U39:Y39,"X")),0) -> 0 | T39: =IF(_xlfn.XLOOKUP(MAX(Q39:S39),Q39:S39,$Q$1:$S$1)='Master Score'!G39,1,0) -> 0 | U39: 1 | V39: 1 | W39: 1 | X39: 1 | Y39: 1
M40: 46194 | N40: H | O40: Uruguay | P40: Cabo Verde | Q40: =IFERROR(COUNTIF(U40:Y40,1)/(COUNT(U40:Y40)+COUNTIF(U40:Y40,"X")),0) -> 1 | R40: =IFERROR(COUNTIF(U40:Y40,2)/(COUNT(U40:Y40)+COUNTIF(U40:Y40,"X")),0) -> 0 | S40: =IFERROR(COUNTIF(U40:Y40,"X")/(COUNT(U40:Y40)+COUNTIF(U40:Y40,"X")),0) -> 0 | T40: =IF(_xlfn.XLOOKUP(MAX(Q40:S40),Q40:S40,$Q$1:$S$1)='Master Score'!G40,1,0) -> 0 | U40: 1 | V40: 1 | W40: 1 | X40: 1 | Y40: 1
...

Sheet Sheet2
A1: Date | B1: Time | D1: Group | E1: Home | F1: Away | G1: =Predictions!F1 -> Matthew O'Brien | H1: =Predictions!H1 -> Aaron Twiss | I1: =Predictions!J1 -> Arion Aliu | J1: =Predictions!L1 -> Rayan Zaibag | K1: =Predictions!N1 -> Jorge Lopez
A2: 46184 | B2: 0.83333333 | C2: = | D2: A | E2: Mexico | F2: South Africa | G2: {=_xlfn.IFS(Predictions!F4=1,$E2,Predictions!F4="X","Draw",Predictions!F4=2,$F2)} -> Mexico | H2: {=_xlfn.IFS(Predictions!H4=1,$E2,Predictions!H4="X","Draw",Predictions!H4=2,$F2)} -> Mexico | I2: {=_xlfn.IFS(Predictions!J4=1,$E2,Predictions!J4="X","Draw",Predictions!J4=2,$F2)} -> Mexico | J2: {=_xlfn.IFS(Predictions!L4=1,$E2,Predictions!L4="X","Draw",Predictions!L4=2,$F2)} -> Mexico | K2: {=_xlfn.IFS(Predictions!N4=1,$E2,Predictions!N4="X","Draw",Predictions!N4=2,$F2)} -> Mexico
A3: 46185 | B3: 0.125 | D3: A | E3: South Korea | F3: Czechia | G3: {=_xlfn.IFS(Predictions!F5=1,$E3,Predictions!F5="X","Draw",Predictions!F5=2,$F3)} -> South Korea | H3: {=_xlfn.IFS(Predictions!H5=1,$E3,Predictions!H5="X","Draw",Predictions!H5=2,$F3)} -> Draw | I3: {=_xlfn.IFS(Predictions!J5=1,$E3,Predictions!J5="X","Draw",Predictions!J5=2,$F3)} -> South Korea | J3: {=_xlfn.IFS(Predictions!L5=1,$E3,Predictions!L5="X","Draw",Predictions!L5=2,$F3)} -> Draw | K3: {=_xlfn.IFS(Predictions!N5=1,$E3,Predictions!N5="X","Draw",Predictions!N5=2,$F3)} -> South Korea
A4: 46185 | B4: 0.83333333 | D4: B | E4: Canada | F4: Bosnia and Herzegovina | G4: {=_xlfn.IFS(Predictions!F6=1,$E4,Predictions!F6="X","Draw",Predictions!F6=2,$F4)} -> Canada | H4: {=_xlfn.IFS(Predictions!H6=1,$E4,Predictions!H6="X","Draw",Predictions!H6=2,$F4)} -> Draw | I4: {=_xlfn.IFS(Predictions!J6=1,$E4,Predictions!J6="X","Draw",Predictions!J6=2,$F4)} -> Bosnia and Herzegovina | J4: {=_xlfn.IFS(Predictions!L6=1,$E4,Predictions!L6="X","Draw",Predictions!L6=2,$F4)} -> Draw | K4: {=_xlfn.IFS(Predictions!N6=1,$E4,Predictions!N6="X","Draw",Predictions!N6=2,$F4)} -> Canada
A5: 46186 | B5: 0.083333333 | D5: D | E5: USA | F5: Paraguay | G5: {=_xlfn.IFS(Predictions!F7=1,$E5,Predictions!F7="X","Draw",Predictions!F7=2,$F5)} -> USA | H5: {=_xlfn.IFS(Predictions!H7=1,$E5,Predictions!H7="X","Draw",Predictions!H7=2,$F5)} -> Paraguay | I5: {=_xlfn.IFS(Predictions!J7=1,$E5,Predictions!J7="X","Draw",Predictions!J7=2,$F5)} -> USA | J5: {=_xlfn.IFS(Predictions!L7=1,$E5,Predictions!L7="X","Draw",Predictions!L7=2,$F5)} -> USA | K5: {=_xlfn.IFS(Predictions!N7=1,$E5,Predictions!N7="X","Draw",Predictions!N7=2,$F5)} -> USA
A6: 46186 | B6: 0.83333333 | D6: B | E6: Qatar | F6: Switzerland | G6: {=_xlfn.IFS(Predictions!F8=1,$E6,Predictions!F8="X","Draw",Predictions!F8=2,$F6)} -> Switzerland | H6: {=_xlfn.IFS(Predictions!H8=1,$E6,Predictions!H8="X","Draw",Predictions!H8=2,$F6)} -> Switzerland | I6: {=_xlfn.IFS(Predictions!J8=1,$E6,Predictions!J8="X","Draw",Predictions!J8=2,$F6)} -> Switzerland | J6: {=_xlfn.IFS(Predictions!L8=1,$E6,Predictions!L8="X","Draw",Predictions!L8=2,$F6)} -> Switzerland | K6: {=_xlfn.IFS(Predictions!N8=1,$E6,Predictions!N8="X","Draw",Predictions!N8=2,$F6)} -> Switzerland
